[2016-11-17 16:36:42] DEBUG [django.db.backends:90] (0.001) 
            SELECT name, type FROM sqlite_master
            WHERE type in ('table', 'view') AND NOT name='sqlite_sequence'
            ORDER BY name; args=None
[2016-11-17 16:36:42] DEBUG [django.db.backends:90] (0.000) SELECT "django_migrations"."app", "django_migrations"."name" FROM "django_migrations"; args=()
[2016-11-17 16:37:06] DEBUG [django.template:929] Exception while resolving variable 'name' in template 'unknown'.
Traceback (most recent call last):
  File "D:\henry2\vemo\ve_vemo\lib\site-packages\django\core\handlers\exception.py", line 39, in inner
    response = get_response(request)
  File "D:\henry2\vemo\ve_vemo\lib\site-packages\django\core\handlers\base.py", line 172, in _get_response
    resolver_match = resolver.resolve(request.path_info)
  File "D:\henry2\vemo\ve_vemo\lib\site-packages\django\urls\resolvers.py", line 300, in resolve
    raise Resolver404({'tried': tried, 'path': new_path})
django.urls.exceptions.Resolver404: {'tried': [[<RegexURLResolver <RegexURLPattern list> (admin:admin) ^admin/>], [<RegexURLResolver <module 'django.contrib.admindocs.urls' from 'D:\\henry2\\vemo\\ve_vemo\\lib\\site-packages\\django\\contrib\\admindocs\\urls.py'> (None:None) ^admin/doc/>], [<RegexURLResolver <module 'rest_framework.urls' from 'D:\\henry2\\vemo\\ve_vemo\\lib\\site-packages\\rest_framework\\urls.py'> (rest_framework:rest_framework) ^api-auth/>], [<RegexURLResolver <module 'oauth2_provider.urls' from 'D:\\henry2\\vemo\\ve_vemo\\lib\\site-packages\\oauth2_provider\\urls.py'> (None:oauth2_provider) ^o/>], [<RegexURLResolver <module 'vemo_service_apps.auths_api.urls' from 'D:\\henry2\\vemo\\vemo_service\\vemo_service_apps\\auths_api\\urls.py'> (None:None) ^api/auths/>], [<RegexURLResolver <module 'vemo_service_apps.catalogo_api.urls' from 'D:\\henry2\\vemo\\vemo_service\\vemo_service_apps\\catalogo_api\\urls.py'> (None:None) ^api/catalogo/>]], 'path': ''}

During handling of the above exception, another exception occurred:

Traceback (most recent call last):
  File "D:\henry2\vemo\ve_vemo\lib\site-packages\django\template\base.py", line 885, in _resolve_lookup
    current = current[bit]
TypeError: 'RegexURLResolver' object is not subscriptable

During handling of the above exception, another exception occurred:

Traceback (most recent call last):
  File "D:\henry2\vemo\ve_vemo\lib\site-packages\django\template\base.py", line 893, in _resolve_lookup
    current = getattr(current, bit)
AttributeError: 'RegexURLResolver' object has no attribute 'name'

During handling of the above exception, another exception occurred:

Traceback (most recent call last):
  File "D:\henry2\vemo\ve_vemo\lib\site-packages\django\template\base.py", line 900, in _resolve_lookup
    current = current[int(bit)]
ValueError: invalid literal for int() with base 10: 'name'

During handling of the above exception, another exception occurred:

Traceback (most recent call last):
  File "D:\henry2\vemo\ve_vemo\lib\site-packages\django\template\base.py", line 907, in _resolve_lookup
    (bit, current))  # missing attribute
django.template.base.VariableDoesNotExist: Failed lookup for key [name] in '<RegexURLResolver <RegexURLPattern list> (admin:admin) ^admin/>'
[2016-11-17 16:37:06] DEBUG [django.template:929] Exception while resolving variable 'name' in template 'unknown'.
Traceback (most recent call last):
  File "D:\henry2\vemo\ve_vemo\lib\site-packages\django\core\handlers\exception.py", line 39, in inner
    response = get_response(request)
  File "D:\henry2\vemo\ve_vemo\lib\site-packages\django\core\handlers\base.py", line 172, in _get_response
    resolver_match = resolver.resolve(request.path_info)
  File "D:\henry2\vemo\ve_vemo\lib\site-packages\django\urls\resolvers.py", line 300, in resolve
    raise Resolver404({'tried': tried, 'path': new_path})
django.urls.exceptions.Resolver404: {'tried': [[<RegexURLResolver <RegexURLPattern list> (admin:admin) ^admin/>], [<RegexURLResolver <module 'django.contrib.admindocs.urls' from 'D:\\henry2\\vemo\\ve_vemo\\lib\\site-packages\\django\\contrib\\admindocs\\urls.py'> (None:None) ^admin/doc/>], [<RegexURLResolver <module 'rest_framework.urls' from 'D:\\henry2\\vemo\\ve_vemo\\lib\\site-packages\\rest_framework\\urls.py'> (rest_framework:rest_framework) ^api-auth/>], [<RegexURLResolver <module 'oauth2_provider.urls' from 'D:\\henry2\\vemo\\ve_vemo\\lib\\site-packages\\oauth2_provider\\urls.py'> (None:oauth2_provider) ^o/>], [<RegexURLResolver <module 'vemo_service_apps.auths_api.urls' from 'D:\\henry2\\vemo\\vemo_service\\vemo_service_apps\\auths_api\\urls.py'> (None:None) ^api/auths/>], [<RegexURLResolver <module 'vemo_service_apps.catalogo_api.urls' from 'D:\\henry2\\vemo\\vemo_service\\vemo_service_apps\\catalogo_api\\urls.py'> (None:None) ^api/catalogo/>]], 'path': ''}

During handling of the above exception, another exception occurred:

Traceback (most recent call last):
  File "D:\henry2\vemo\ve_vemo\lib\site-packages\django\template\base.py", line 885, in _resolve_lookup
    current = current[bit]
TypeError: 'RegexURLResolver' object is not subscriptable

During handling of the above exception, another exception occurred:

Traceback (most recent call last):
  File "D:\henry2\vemo\ve_vemo\lib\site-packages\django\template\base.py", line 893, in _resolve_lookup
    current = getattr(current, bit)
AttributeError: 'RegexURLResolver' object has no attribute 'name'

During handling of the above exception, another exception occurred:

Traceback (most recent call last):
  File "D:\henry2\vemo\ve_vemo\lib\site-packages\django\template\base.py", line 900, in _resolve_lookup
    current = current[int(bit)]
ValueError: invalid literal for int() with base 10: 'name'

During handling of the above exception, another exception occurred:

Traceback (most recent call last):
  File "D:\henry2\vemo\ve_vemo\lib\site-packages\django\template\base.py", line 907, in _resolve_lookup
    (bit, current))  # missing attribute
django.template.base.VariableDoesNotExist: Failed lookup for key [name] in "<RegexURLResolver <module 'django.contrib.admindocs.urls' from 'D:\\\\henry2\\\\vemo\\\\ve_vemo\\\\lib\\\\site-packages\\\\django\\\\contrib\\\\admindocs\\\\urls.py'> (None:None) ^admin/doc/>"
[2016-11-17 16:37:06] DEBUG [django.template:929] Exception while resolving variable 'name' in template 'unknown'.
Traceback (most recent call last):
  File "D:\henry2\vemo\ve_vemo\lib\site-packages\django\core\handlers\exception.py", line 39, in inner
    response = get_response(request)
  File "D:\henry2\vemo\ve_vemo\lib\site-packages\django\core\handlers\base.py", line 172, in _get_response
    resolver_match = resolver.resolve(request.path_info)
  File "D:\henry2\vemo\ve_vemo\lib\site-packages\django\urls\resolvers.py", line 300, in resolve
    raise Resolver404({'tried': tried, 'path': new_path})
django.urls.exceptions.Resolver404: {'tried': [[<RegexURLResolver <RegexURLPattern list> (admin:admin) ^admin/>], [<RegexURLResolver <module 'django.contrib.admindocs.urls' from 'D:\\henry2\\vemo\\ve_vemo\\lib\\site-packages\\django\\contrib\\admindocs\\urls.py'> (None:None) ^admin/doc/>], [<RegexURLResolver <module 'rest_framework.urls' from 'D:\\henry2\\vemo\\ve_vemo\\lib\\site-packages\\rest_framework\\urls.py'> (rest_framework:rest_framework) ^api-auth/>], [<RegexURLResolver <module 'oauth2_provider.urls' from 'D:\\henry2\\vemo\\ve_vemo\\lib\\site-packages\\oauth2_provider\\urls.py'> (None:oauth2_provider) ^o/>], [<RegexURLResolver <module 'vemo_service_apps.auths_api.urls' from 'D:\\henry2\\vemo\\vemo_service\\vemo_service_apps\\auths_api\\urls.py'> (None:None) ^api/auths/>], [<RegexURLResolver <module 'vemo_service_apps.catalogo_api.urls' from 'D:\\henry2\\vemo\\vemo_service\\vemo_service_apps\\catalogo_api\\urls.py'> (None:None) ^api/catalogo/>]], 'path': ''}

During handling of the above exception, another exception occurred:

Traceback (most recent call last):
  File "D:\henry2\vemo\ve_vemo\lib\site-packages\django\template\base.py", line 885, in _resolve_lookup
    current = current[bit]
TypeError: 'RegexURLResolver' object is not subscriptable

During handling of the above exception, another exception occurred:

Traceback (most recent call last):
  File "D:\henry2\vemo\ve_vemo\lib\site-packages\django\template\base.py", line 893, in _resolve_lookup
    current = getattr(current, bit)
AttributeError: 'RegexURLResolver' object has no attribute 'name'

During handling of the above exception, another exception occurred:

Traceback (most recent call last):
  File "D:\henry2\vemo\ve_vemo\lib\site-packages\django\template\base.py", line 900, in _resolve_lookup
    current = current[int(bit)]
ValueError: invalid literal for int() with base 10: 'name'

During handling of the above exception, another exception occurred:

Traceback (most recent call last):
  File "D:\henry2\vemo\ve_vemo\lib\site-packages\django\template\base.py", line 907, in _resolve_lookup
    (bit, current))  # missing attribute
django.template.base.VariableDoesNotExist: Failed lookup for key [name] in "<RegexURLResolver <module 'rest_framework.urls' from 'D:\\\\henry2\\\\vemo\\\\ve_vemo\\\\lib\\\\site-packages\\\\rest_framework\\\\urls.py'> (rest_framework:rest_framework) ^api-auth/>"
[2016-11-17 16:37:06] DEBUG [django.template:929] Exception while resolving variable 'name' in template 'unknown'.
Traceback (most recent call last):
  File "D:\henry2\vemo\ve_vemo\lib\site-packages\django\core\handlers\exception.py", line 39, in inner
    response = get_response(request)
  File "D:\henry2\vemo\ve_vemo\lib\site-packages\django\core\handlers\base.py", line 172, in _get_response
    resolver_match = resolver.resolve(request.path_info)
  File "D:\henry2\vemo\ve_vemo\lib\site-packages\django\urls\resolvers.py", line 300, in resolve
    raise Resolver404({'tried': tried, 'path': new_path})
django.urls.exceptions.Resolver404: {'tried': [[<RegexURLResolver <RegexURLPattern list> (admin:admin) ^admin/>], [<RegexURLResolver <module 'django.contrib.admindocs.urls' from 'D:\\henry2\\vemo\\ve_vemo\\lib\\site-packages\\django\\contrib\\admindocs\\urls.py'> (None:None) ^admin/doc/>], [<RegexURLResolver <module 'rest_framework.urls' from 'D:\\henry2\\vemo\\ve_vemo\\lib\\site-packages\\rest_framework\\urls.py'> (rest_framework:rest_framework) ^api-auth/>], [<RegexURLResolver <module 'oauth2_provider.urls' from 'D:\\henry2\\vemo\\ve_vemo\\lib\\site-packages\\oauth2_provider\\urls.py'> (None:oauth2_provider) ^o/>], [<RegexURLResolver <module 'vemo_service_apps.auths_api.urls' from 'D:\\henry2\\vemo\\vemo_service\\vemo_service_apps\\auths_api\\urls.py'> (None:None) ^api/auths/>], [<RegexURLResolver <module 'vemo_service_apps.catalogo_api.urls' from 'D:\\henry2\\vemo\\vemo_service\\vemo_service_apps\\catalogo_api\\urls.py'> (None:None) ^api/catalogo/>]], 'path': ''}

During handling of the above exception, another exception occurred:

Traceback (most recent call last):
  File "D:\henry2\vemo\ve_vemo\lib\site-packages\django\template\base.py", line 885, in _resolve_lookup
    current = current[bit]
TypeError: 'RegexURLResolver' object is not subscriptable

During handling of the above exception, another exception occurred:

Traceback (most recent call last):
  File "D:\henry2\vemo\ve_vemo\lib\site-packages\django\template\base.py", line 893, in _resolve_lookup
    current = getattr(current, bit)
AttributeError: 'RegexURLResolver' object has no attribute 'name'

During handling of the above exception, another exception occurred:

Traceback (most recent call last):
  File "D:\henry2\vemo\ve_vemo\lib\site-packages\django\template\base.py", line 900, in _resolve_lookup
    current = current[int(bit)]
ValueError: invalid literal for int() with base 10: 'name'

During handling of the above exception, another exception occurred:

Traceback (most recent call last):
  File "D:\henry2\vemo\ve_vemo\lib\site-packages\django\template\base.py", line 907, in _resolve_lookup
    (bit, current))  # missing attribute
django.template.base.VariableDoesNotExist: Failed lookup for key [name] in "<RegexURLResolver <module 'oauth2_provider.urls' from 'D:\\\\henry2\\\\vemo\\\\ve_vemo\\\\lib\\\\site-packages\\\\oauth2_provider\\\\urls.py'> (None:oauth2_provider) ^o/>"
[2016-11-17 16:37:06] DEBUG [django.template:929] Exception while resolving variable 'name' in template 'unknown'.
Traceback (most recent call last):
  File "D:\henry2\vemo\ve_vemo\lib\site-packages\django\core\handlers\exception.py", line 39, in inner
    response = get_response(request)
  File "D:\henry2\vemo\ve_vemo\lib\site-packages\django\core\handlers\base.py", line 172, in _get_response
    resolver_match = resolver.resolve(request.path_info)
  File "D:\henry2\vemo\ve_vemo\lib\site-packages\django\urls\resolvers.py", line 300, in resolve
    raise Resolver404({'tried': tried, 'path': new_path})
django.urls.exceptions.Resolver404: {'tried': [[<RegexURLResolver <RegexURLPattern list> (admin:admin) ^admin/>], [<RegexURLResolver <module 'django.contrib.admindocs.urls' from 'D:\\henry2\\vemo\\ve_vemo\\lib\\site-packages\\django\\contrib\\admindocs\\urls.py'> (None:None) ^admin/doc/>], [<RegexURLResolver <module 'rest_framework.urls' from 'D:\\henry2\\vemo\\ve_vemo\\lib\\site-packages\\rest_framework\\urls.py'> (rest_framework:rest_framework) ^api-auth/>], [<RegexURLResolver <module 'oauth2_provider.urls' from 'D:\\henry2\\vemo\\ve_vemo\\lib\\site-packages\\oauth2_provider\\urls.py'> (None:oauth2_provider) ^o/>], [<RegexURLResolver <module 'vemo_service_apps.auths_api.urls' from 'D:\\henry2\\vemo\\vemo_service\\vemo_service_apps\\auths_api\\urls.py'> (None:None) ^api/auths/>], [<RegexURLResolver <module 'vemo_service_apps.catalogo_api.urls' from 'D:\\henry2\\vemo\\vemo_service\\vemo_service_apps\\catalogo_api\\urls.py'> (None:None) ^api/catalogo/>]], 'path': ''}

During handling of the above exception, another exception occurred:

Traceback (most recent call last):
  File "D:\henry2\vemo\ve_vemo\lib\site-packages\django\template\base.py", line 885, in _resolve_lookup
    current = current[bit]
TypeError: 'RegexURLResolver' object is not subscriptable

During handling of the above exception, another exception occurred:

Traceback (most recent call last):
  File "D:\henry2\vemo\ve_vemo\lib\site-packages\django\template\base.py", line 893, in _resolve_lookup
    current = getattr(current, bit)
AttributeError: 'RegexURLResolver' object has no attribute 'name'

During handling of the above exception, another exception occurred:

Traceback (most recent call last):
  File "D:\henry2\vemo\ve_vemo\lib\site-packages\django\template\base.py", line 900, in _resolve_lookup
    current = current[int(bit)]
ValueError: invalid literal for int() with base 10: 'name'

During handling of the above exception, another exception occurred:

Traceback (most recent call last):
  File "D:\henry2\vemo\ve_vemo\lib\site-packages\django\template\base.py", line 907, in _resolve_lookup
    (bit, current))  # missing attribute
django.template.base.VariableDoesNotExist: Failed lookup for key [name] in "<RegexURLResolver <module 'vemo_service_apps.auths_api.urls' from 'D:\\\\henry2\\\\vemo\\\\vemo_service\\\\vemo_service_apps\\\\auths_api\\\\urls.py'> (None:None) ^api/auths/>"
[2016-11-17 16:37:06] DEBUG [django.template:929] Exception while resolving variable 'name' in template 'unknown'.
Traceback (most recent call last):
  File "D:\henry2\vemo\ve_vemo\lib\site-packages\django\core\handlers\exception.py", line 39, in inner
    response = get_response(request)
  File "D:\henry2\vemo\ve_vemo\lib\site-packages\django\core\handlers\base.py", line 172, in _get_response
    resolver_match = resolver.resolve(request.path_info)
  File "D:\henry2\vemo\ve_vemo\lib\site-packages\django\urls\resolvers.py", line 300, in resolve
    raise Resolver404({'tried': tried, 'path': new_path})
django.urls.exceptions.Resolver404: {'tried': [[<RegexURLResolver <RegexURLPattern list> (admin:admin) ^admin/>], [<RegexURLResolver <module 'django.contrib.admindocs.urls' from 'D:\\henry2\\vemo\\ve_vemo\\lib\\site-packages\\django\\contrib\\admindocs\\urls.py'> (None:None) ^admin/doc/>], [<RegexURLResolver <module 'rest_framework.urls' from 'D:\\henry2\\vemo\\ve_vemo\\lib\\site-packages\\rest_framework\\urls.py'> (rest_framework:rest_framework) ^api-auth/>], [<RegexURLResolver <module 'oauth2_provider.urls' from 'D:\\henry2\\vemo\\ve_vemo\\lib\\site-packages\\oauth2_provider\\urls.py'> (None:oauth2_provider) ^o/>], [<RegexURLResolver <module 'vemo_service_apps.auths_api.urls' from 'D:\\henry2\\vemo\\vemo_service\\vemo_service_apps\\auths_api\\urls.py'> (None:None) ^api/auths/>], [<RegexURLResolver <module 'vemo_service_apps.catalogo_api.urls' from 'D:\\henry2\\vemo\\vemo_service\\vemo_service_apps\\catalogo_api\\urls.py'> (None:None) ^api/catalogo/>]], 'path': ''}

During handling of the above exception, another exception occurred:

Traceback (most recent call last):
  File "D:\henry2\vemo\ve_vemo\lib\site-packages\django\template\base.py", line 885, in _resolve_lookup
    current = current[bit]
TypeError: 'RegexURLResolver' object is not subscriptable

During handling of the above exception, another exception occurred:

Traceback (most recent call last):
  File "D:\henry2\vemo\ve_vemo\lib\site-packages\django\template\base.py", line 893, in _resolve_lookup
    current = getattr(current, bit)
AttributeError: 'RegexURLResolver' object has no attribute 'name'

During handling of the above exception, another exception occurred:

Traceback (most recent call last):
  File "D:\henry2\vemo\ve_vemo\lib\site-packages\django\template\base.py", line 900, in _resolve_lookup
    current = current[int(bit)]
ValueError: invalid literal for int() with base 10: 'name'

During handling of the above exception, another exception occurred:

Traceback (most recent call last):
  File "D:\henry2\vemo\ve_vemo\lib\site-packages\django\template\base.py", line 907, in _resolve_lookup
    (bit, current))  # missing attribute
django.template.base.VariableDoesNotExist: Failed lookup for key [name] in "<RegexURLResolver <module 'vemo_service_apps.catalogo_api.urls' from 'D:\\\\henry2\\\\vemo\\\\vemo_service\\\\vemo_service_apps\\\\catalogo_api\\\\urls.py'> (None:None) ^api/catalogo/>"
[2016-11-17 16:37:06] WARNING [django.request:152] Not Found: /
[2016-11-17 16:37:06] WARNING [django.server:131] "GET / HTTP/1.1" 404 2455
[2016-11-17 16:37:07] DEBUG [django.template:929] Exception while resolving variable 'name' in template 'unknown'.
Traceback (most recent call last):
  File "D:\henry2\vemo\ve_vemo\lib\site-packages\django\core\handlers\exception.py", line 39, in inner
    response = get_response(request)
  File "D:\henry2\vemo\ve_vemo\lib\site-packages\django\core\handlers\base.py", line 172, in _get_response
    resolver_match = resolver.resolve(request.path_info)
  File "D:\henry2\vemo\ve_vemo\lib\site-packages\django\urls\resolvers.py", line 300, in resolve
    raise Resolver404({'tried': tried, 'path': new_path})
django.urls.exceptions.Resolver404: {'tried': [[<RegexURLResolver <RegexURLPattern list> (admin:admin) ^admin/>], [<RegexURLResolver <module 'django.contrib.admindocs.urls' from 'D:\\henry2\\vemo\\ve_vemo\\lib\\site-packages\\django\\contrib\\admindocs\\urls.py'> (None:None) ^admin/doc/>], [<RegexURLResolver <module 'rest_framework.urls' from 'D:\\henry2\\vemo\\ve_vemo\\lib\\site-packages\\rest_framework\\urls.py'> (rest_framework:rest_framework) ^api-auth/>], [<RegexURLResolver <module 'oauth2_provider.urls' from 'D:\\henry2\\vemo\\ve_vemo\\lib\\site-packages\\oauth2_provider\\urls.py'> (None:oauth2_provider) ^o/>], [<RegexURLResolver <module 'vemo_service_apps.auths_api.urls' from 'D:\\henry2\\vemo\\vemo_service\\vemo_service_apps\\auths_api\\urls.py'> (None:None) ^api/auths/>], [<RegexURLResolver <module 'vemo_service_apps.catalogo_api.urls' from 'D:\\henry2\\vemo\\vemo_service\\vemo_service_apps\\catalogo_api\\urls.py'> (None:None) ^api/catalogo/>]], 'path': 'favicon.ico'}

During handling of the above exception, another exception occurred:

Traceback (most recent call last):
  File "D:\henry2\vemo\ve_vemo\lib\site-packages\django\template\base.py", line 885, in _resolve_lookup
    current = current[bit]
TypeError: 'RegexURLResolver' object is not subscriptable

During handling of the above exception, another exception occurred:

Traceback (most recent call last):
  File "D:\henry2\vemo\ve_vemo\lib\site-packages\django\template\base.py", line 893, in _resolve_lookup
    current = getattr(current, bit)
AttributeError: 'RegexURLResolver' object has no attribute 'name'

During handling of the above exception, another exception occurred:

Traceback (most recent call last):
  File "D:\henry2\vemo\ve_vemo\lib\site-packages\django\template\base.py", line 900, in _resolve_lookup
    current = current[int(bit)]
ValueError: invalid literal for int() with base 10: 'name'

During handling of the above exception, another exception occurred:

Traceback (most recent call last):
  File "D:\henry2\vemo\ve_vemo\lib\site-packages\django\template\base.py", line 907, in _resolve_lookup
    (bit, current))  # missing attribute
django.template.base.VariableDoesNotExist: Failed lookup for key [name] in '<RegexURLResolver <RegexURLPattern list> (admin:admin) ^admin/>'
[2016-11-17 16:37:07] DEBUG [django.template:929] Exception while resolving variable 'name' in template 'unknown'.
Traceback (most recent call last):
  File "D:\henry2\vemo\ve_vemo\lib\site-packages\django\core\handlers\exception.py", line 39, in inner
    response = get_response(request)
  File "D:\henry2\vemo\ve_vemo\lib\site-packages\django\core\handlers\base.py", line 172, in _get_response
    resolver_match = resolver.resolve(request.path_info)
  File "D:\henry2\vemo\ve_vemo\lib\site-packages\django\urls\resolvers.py", line 300, in resolve
    raise Resolver404({'tried': tried, 'path': new_path})
django.urls.exceptions.Resolver404: {'tried': [[<RegexURLResolver <RegexURLPattern list> (admin:admin) ^admin/>], [<RegexURLResolver <module 'django.contrib.admindocs.urls' from 'D:\\henry2\\vemo\\ve_vemo\\lib\\site-packages\\django\\contrib\\admindocs\\urls.py'> (None:None) ^admin/doc/>], [<RegexURLResolver <module 'rest_framework.urls' from 'D:\\henry2\\vemo\\ve_vemo\\lib\\site-packages\\rest_framework\\urls.py'> (rest_framework:rest_framework) ^api-auth/>], [<RegexURLResolver <module 'oauth2_provider.urls' from 'D:\\henry2\\vemo\\ve_vemo\\lib\\site-packages\\oauth2_provider\\urls.py'> (None:oauth2_provider) ^o/>], [<RegexURLResolver <module 'vemo_service_apps.auths_api.urls' from 'D:\\henry2\\vemo\\vemo_service\\vemo_service_apps\\auths_api\\urls.py'> (None:None) ^api/auths/>], [<RegexURLResolver <module 'vemo_service_apps.catalogo_api.urls' from 'D:\\henry2\\vemo\\vemo_service\\vemo_service_apps\\catalogo_api\\urls.py'> (None:None) ^api/catalogo/>]], 'path': 'favicon.ico'}

During handling of the above exception, another exception occurred:

Traceback (most recent call last):
  File "D:\henry2\vemo\ve_vemo\lib\site-packages\django\template\base.py", line 885, in _resolve_lookup
    current = current[bit]
TypeError: 'RegexURLResolver' object is not subscriptable

During handling of the above exception, another exception occurred:

Traceback (most recent call last):
  File "D:\henry2\vemo\ve_vemo\lib\site-packages\django\template\base.py", line 893, in _resolve_lookup
    current = getattr(current, bit)
AttributeError: 'RegexURLResolver' object has no attribute 'name'

During handling of the above exception, another exception occurred:

Traceback (most recent call last):
  File "D:\henry2\vemo\ve_vemo\lib\site-packages\django\template\base.py", line 900, in _resolve_lookup
    current = current[int(bit)]
ValueError: invalid literal for int() with base 10: 'name'

During handling of the above exception, another exception occurred:

Traceback (most recent call last):
  File "D:\henry2\vemo\ve_vemo\lib\site-packages\django\template\base.py", line 907, in _resolve_lookup
    (bit, current))  # missing attribute
django.template.base.VariableDoesNotExist: Failed lookup for key [name] in '<RegexURLResolver <RegexURLPattern list> (admin:admin) ^admin/>'
[2016-11-17 16:37:07] DEBUG [django.template:929] Exception while resolving variable 'name' in template 'unknown'.
Traceback (most recent call last):
  File "D:\henry2\vemo\ve_vemo\lib\site-packages\django\core\handlers\exception.py", line 39, in inner
    response = get_response(request)
  File "D:\henry2\vemo\ve_vemo\lib\site-packages\django\core\handlers\base.py", line 172, in _get_response
    resolver_match = resolver.resolve(request.path_info)
  File "D:\henry2\vemo\ve_vemo\lib\site-packages\django\urls\resolvers.py", line 300, in resolve
    raise Resolver404({'tried': tried, 'path': new_path})
django.urls.exceptions.Resolver404: {'tried': [[<RegexURLResolver <RegexURLPattern list> (admin:admin) ^admin/>], [<RegexURLResolver <module 'django.contrib.admindocs.urls' from 'D:\\henry2\\vemo\\ve_vemo\\lib\\site-packages\\django\\contrib\\admindocs\\urls.py'> (None:None) ^admin/doc/>], [<RegexURLResolver <module 'rest_framework.urls' from 'D:\\henry2\\vemo\\ve_vemo\\lib\\site-packages\\rest_framework\\urls.py'> (rest_framework:rest_framework) ^api-auth/>], [<RegexURLResolver <module 'oauth2_provider.urls' from 'D:\\henry2\\vemo\\ve_vemo\\lib\\site-packages\\oauth2_provider\\urls.py'> (None:oauth2_provider) ^o/>], [<RegexURLResolver <module 'vemo_service_apps.auths_api.urls' from 'D:\\henry2\\vemo\\vemo_service\\vemo_service_apps\\auths_api\\urls.py'> (None:None) ^api/auths/>], [<RegexURLResolver <module 'vemo_service_apps.catalogo_api.urls' from 'D:\\henry2\\vemo\\vemo_service\\vemo_service_apps\\catalogo_api\\urls.py'> (None:None) ^api/catalogo/>]], 'path': 'favicon.ico'}

During handling of the above exception, another exception occurred:

Traceback (most recent call last):
  File "D:\henry2\vemo\ve_vemo\lib\site-packages\django\template\base.py", line 885, in _resolve_lookup
    current = current[bit]
TypeError: 'RegexURLResolver' object is not subscriptable

During handling of the above exception, another exception occurred:

Traceback (most recent call last):
  File "D:\henry2\vemo\ve_vemo\lib\site-packages\django\template\base.py", line 893, in _resolve_lookup
    current = getattr(current, bit)
AttributeError: 'RegexURLResolver' object has no attribute 'name'

During handling of the above exception, another exception occurred:

Traceback (most recent call last):
  File "D:\henry2\vemo\ve_vemo\lib\site-packages\django\template\base.py", line 900, in _resolve_lookup
    current = current[int(bit)]
ValueError: invalid literal for int() with base 10: 'name'

During handling of the above exception, another exception occurred:

Traceback (most recent call last):
  File "D:\henry2\vemo\ve_vemo\lib\site-packages\django\template\base.py", line 907, in _resolve_lookup
    (bit, current))  # missing attribute
django.template.base.VariableDoesNotExist: Failed lookup for key [name] in "<RegexURLResolver <module 'django.contrib.admindocs.urls' from 'D:\\\\henry2\\\\vemo\\\\ve_vemo\\\\lib\\\\site-packages\\\\django\\\\contrib\\\\admindocs\\\\urls.py'> (None:None) ^admin/doc/>"
[2016-11-17 16:37:07] DEBUG [django.template:929] Exception while resolving variable 'name' in template 'unknown'.
Traceback (most recent call last):
  File "D:\henry2\vemo\ve_vemo\lib\site-packages\django\core\handlers\exception.py", line 39, in inner
    response = get_response(request)
  File "D:\henry2\vemo\ve_vemo\lib\site-packages\django\core\handlers\base.py", line 172, in _get_response
    resolver_match = resolver.resolve(request.path_info)
  File "D:\henry2\vemo\ve_vemo\lib\site-packages\django\urls\resolvers.py", line 300, in resolve
    raise Resolver404({'tried': tried, 'path': new_path})
django.urls.exceptions.Resolver404: {'tried': [[<RegexURLResolver <RegexURLPattern list> (admin:admin) ^admin/>], [<RegexURLResolver <module 'django.contrib.admindocs.urls' from 'D:\\henry2\\vemo\\ve_vemo\\lib\\site-packages\\django\\contrib\\admindocs\\urls.py'> (None:None) ^admin/doc/>], [<RegexURLResolver <module 'rest_framework.urls' from 'D:\\henry2\\vemo\\ve_vemo\\lib\\site-packages\\rest_framework\\urls.py'> (rest_framework:rest_framework) ^api-auth/>], [<RegexURLResolver <module 'oauth2_provider.urls' from 'D:\\henry2\\vemo\\ve_vemo\\lib\\site-packages\\oauth2_provider\\urls.py'> (None:oauth2_provider) ^o/>], [<RegexURLResolver <module 'vemo_service_apps.auths_api.urls' from 'D:\\henry2\\vemo\\vemo_service\\vemo_service_apps\\auths_api\\urls.py'> (None:None) ^api/auths/>], [<RegexURLResolver <module 'vemo_service_apps.catalogo_api.urls' from 'D:\\henry2\\vemo\\vemo_service\\vemo_service_apps\\catalogo_api\\urls.py'> (None:None) ^api/catalogo/>]], 'path': 'favicon.ico'}

During handling of the above exception, another exception occurred:

Traceback (most recent call last):
  File "D:\henry2\vemo\ve_vemo\lib\site-packages\django\template\base.py", line 885, in _resolve_lookup
    current = current[bit]
TypeError: 'RegexURLResolver' object is not subscriptable

During handling of the above exception, another exception occurred:

Traceback (most recent call last):
  File "D:\henry2\vemo\ve_vemo\lib\site-packages\django\template\base.py", line 893, in _resolve_lookup
    current = getattr(current, bit)
AttributeError: 'RegexURLResolver' object has no attribute 'name'

During handling of the above exception, another exception occurred:

Traceback (most recent call last):
  File "D:\henry2\vemo\ve_vemo\lib\site-packages\django\template\base.py", line 900, in _resolve_lookup
    current = current[int(bit)]
ValueError: invalid literal for int() with base 10: 'name'

During handling of the above exception, another exception occurred:

Traceback (most recent call last):
  File "D:\henry2\vemo\ve_vemo\lib\site-packages\django\template\base.py", line 907, in _resolve_lookup
    (bit, current))  # missing attribute
django.template.base.VariableDoesNotExist: Failed lookup for key [name] in "<RegexURLResolver <module 'django.contrib.admindocs.urls' from 'D:\\\\henry2\\\\vemo\\\\ve_vemo\\\\lib\\\\site-packages\\\\django\\\\contrib\\\\admindocs\\\\urls.py'> (None:None) ^admin/doc/>"
[2016-11-17 16:37:07] DEBUG [django.template:929] Exception while resolving variable 'name' in template 'unknown'.
Traceback (most recent call last):
  File "D:\henry2\vemo\ve_vemo\lib\site-packages\django\core\handlers\exception.py", line 39, in inner
    response = get_response(request)
  File "D:\henry2\vemo\ve_vemo\lib\site-packages\django\core\handlers\base.py", line 172, in _get_response
    resolver_match = resolver.resolve(request.path_info)
  File "D:\henry2\vemo\ve_vemo\lib\site-packages\django\urls\resolvers.py", line 300, in resolve
    raise Resolver404({'tried': tried, 'path': new_path})
django.urls.exceptions.Resolver404: {'tried': [[<RegexURLResolver <RegexURLPattern list> (admin:admin) ^admin/>], [<RegexURLResolver <module 'django.contrib.admindocs.urls' from 'D:\\henry2\\vemo\\ve_vemo\\lib\\site-packages\\django\\contrib\\admindocs\\urls.py'> (None:None) ^admin/doc/>], [<RegexURLResolver <module 'rest_framework.urls' from 'D:\\henry2\\vemo\\ve_vemo\\lib\\site-packages\\rest_framework\\urls.py'> (rest_framework:rest_framework) ^api-auth/>], [<RegexURLResolver <module 'oauth2_provider.urls' from 'D:\\henry2\\vemo\\ve_vemo\\lib\\site-packages\\oauth2_provider\\urls.py'> (None:oauth2_provider) ^o/>], [<RegexURLResolver <module 'vemo_service_apps.auths_api.urls' from 'D:\\henry2\\vemo\\vemo_service\\vemo_service_apps\\auths_api\\urls.py'> (None:None) ^api/auths/>], [<RegexURLResolver <module 'vemo_service_apps.catalogo_api.urls' from 'D:\\henry2\\vemo\\vemo_service\\vemo_service_apps\\catalogo_api\\urls.py'> (None:None) ^api/catalogo/>]], 'path': 'favicon.ico'}

During handling of the above exception, another exception occurred:

Traceback (most recent call last):
  File "D:\henry2\vemo\ve_vemo\lib\site-packages\django\template\base.py", line 885, in _resolve_lookup
    current = current[bit]
TypeError: 'RegexURLResolver' object is not subscriptable

During handling of the above exception, another exception occurred:

Traceback (most recent call last):
  File "D:\henry2\vemo\ve_vemo\lib\site-packages\django\template\base.py", line 893, in _resolve_lookup
    current = getattr(current, bit)
AttributeError: 'RegexURLResolver' object has no attribute 'name'

During handling of the above exception, another exception occurred:

Traceback (most recent call last):
  File "D:\henry2\vemo\ve_vemo\lib\site-packages\django\template\base.py", line 900, in _resolve_lookup
    current = current[int(bit)]
ValueError: invalid literal for int() with base 10: 'name'

During handling of the above exception, another exception occurred:

Traceback (most recent call last):
  File "D:\henry2\vemo\ve_vemo\lib\site-packages\django\template\base.py", line 907, in _resolve_lookup
    (bit, current))  # missing attribute
django.template.base.VariableDoesNotExist: Failed lookup for key [name] in "<RegexURLResolver <module 'rest_framework.urls' from 'D:\\\\henry2\\\\vemo\\\\ve_vemo\\\\lib\\\\site-packages\\\\rest_framework\\\\urls.py'> (rest_framework:rest_framework) ^api-auth/>"
[2016-11-17 16:37:07] DEBUG [django.template:929] Exception while resolving variable 'name' in template 'unknown'.
Traceback (most recent call last):
  File "D:\henry2\vemo\ve_vemo\lib\site-packages\django\core\handlers\exception.py", line 39, in inner
    response = get_response(request)
  File "D:\henry2\vemo\ve_vemo\lib\site-packages\django\core\handlers\base.py", line 172, in _get_response
    resolver_match = resolver.resolve(request.path_info)
  File "D:\henry2\vemo\ve_vemo\lib\site-packages\django\urls\resolvers.py", line 300, in resolve
    raise Resolver404({'tried': tried, 'path': new_path})
django.urls.exceptions.Resolver404: {'tried': [[<RegexURLResolver <RegexURLPattern list> (admin:admin) ^admin/>], [<RegexURLResolver <module 'django.contrib.admindocs.urls' from 'D:\\henry2\\vemo\\ve_vemo\\lib\\site-packages\\django\\contrib\\admindocs\\urls.py'> (None:None) ^admin/doc/>], [<RegexURLResolver <module 'rest_framework.urls' from 'D:\\henry2\\vemo\\ve_vemo\\lib\\site-packages\\rest_framework\\urls.py'> (rest_framework:rest_framework) ^api-auth/>], [<RegexURLResolver <module 'oauth2_provider.urls' from 'D:\\henry2\\vemo\\ve_vemo\\lib\\site-packages\\oauth2_provider\\urls.py'> (None:oauth2_provider) ^o/>], [<RegexURLResolver <module 'vemo_service_apps.auths_api.urls' from 'D:\\henry2\\vemo\\vemo_service\\vemo_service_apps\\auths_api\\urls.py'> (None:None) ^api/auths/>], [<RegexURLResolver <module 'vemo_service_apps.catalogo_api.urls' from 'D:\\henry2\\vemo\\vemo_service\\vemo_service_apps\\catalogo_api\\urls.py'> (None:None) ^api/catalogo/>]], 'path': 'favicon.ico'}

During handling of the above exception, another exception occurred:

Traceback (most recent call last):
  File "D:\henry2\vemo\ve_vemo\lib\site-packages\django\template\base.py", line 885, in _resolve_lookup
    current = current[bit]
TypeError: 'RegexURLResolver' object is not subscriptable

During handling of the above exception, another exception occurred:

Traceback (most recent call last):
  File "D:\henry2\vemo\ve_vemo\lib\site-packages\django\template\base.py", line 893, in _resolve_lookup
    current = getattr(current, bit)
AttributeError: 'RegexURLResolver' object has no attribute 'name'

During handling of the above exception, another exception occurred:

Traceback (most recent call last):
  File "D:\henry2\vemo\ve_vemo\lib\site-packages\django\template\base.py", line 900, in _resolve_lookup
    current = current[int(bit)]
ValueError: invalid literal for int() with base 10: 'name'

During handling of the above exception, another exception occurred:

Traceback (most recent call last):
  File "D:\henry2\vemo\ve_vemo\lib\site-packages\django\template\base.py", line 907, in _resolve_lookup
    (bit, current))  # missing attribute
django.template.base.VariableDoesNotExist: Failed lookup for key [name] in "<RegexURLResolver <module 'rest_framework.urls' from 'D:\\\\henry2\\\\vemo\\\\ve_vemo\\\\lib\\\\site-packages\\\\rest_framework\\\\urls.py'> (rest_framework:rest_framework) ^api-auth/>"
[2016-11-17 16:37:07] DEBUG [django.template:929] Exception while resolving variable 'name' in template 'unknown'.
Traceback (most recent call last):
  File "D:\henry2\vemo\ve_vemo\lib\site-packages\django\core\handlers\exception.py", line 39, in inner
    response = get_response(request)
  File "D:\henry2\vemo\ve_vemo\lib\site-packages\django\core\handlers\base.py", line 172, in _get_response
    resolver_match = resolver.resolve(request.path_info)
  File "D:\henry2\vemo\ve_vemo\lib\site-packages\django\urls\resolvers.py", line 300, in resolve
    raise Resolver404({'tried': tried, 'path': new_path})
django.urls.exceptions.Resolver404: {'tried': [[<RegexURLResolver <RegexURLPattern list> (admin:admin) ^admin/>], [<RegexURLResolver <module 'django.contrib.admindocs.urls' from 'D:\\henry2\\vemo\\ve_vemo\\lib\\site-packages\\django\\contrib\\admindocs\\urls.py'> (None:None) ^admin/doc/>], [<RegexURLResolver <module 'rest_framework.urls' from 'D:\\henry2\\vemo\\ve_vemo\\lib\\site-packages\\rest_framework\\urls.py'> (rest_framework:rest_framework) ^api-auth/>], [<RegexURLResolver <module 'oauth2_provider.urls' from 'D:\\henry2\\vemo\\ve_vemo\\lib\\site-packages\\oauth2_provider\\urls.py'> (None:oauth2_provider) ^o/>], [<RegexURLResolver <module 'vemo_service_apps.auths_api.urls' from 'D:\\henry2\\vemo\\vemo_service\\vemo_service_apps\\auths_api\\urls.py'> (None:None) ^api/auths/>], [<RegexURLResolver <module 'vemo_service_apps.catalogo_api.urls' from 'D:\\henry2\\vemo\\vemo_service\\vemo_service_apps\\catalogo_api\\urls.py'> (None:None) ^api/catalogo/>]], 'path': 'favicon.ico'}

During handling of the above exception, another exception occurred:

Traceback (most recent call last):
  File "D:\henry2\vemo\ve_vemo\lib\site-packages\django\template\base.py", line 885, in _resolve_lookup
    current = current[bit]
TypeError: 'RegexURLResolver' object is not subscriptable

During handling of the above exception, another exception occurred:

Traceback (most recent call last):
  File "D:\henry2\vemo\ve_vemo\lib\site-packages\django\template\base.py", line 893, in _resolve_lookup
    current = getattr(current, bit)
AttributeError: 'RegexURLResolver' object has no attribute 'name'

During handling of the above exception, another exception occurred:

Traceback (most recent call last):
  File "D:\henry2\vemo\ve_vemo\lib\site-packages\django\template\base.py", line 900, in _resolve_lookup
    current = current[int(bit)]
ValueError: invalid literal for int() with base 10: 'name'

During handling of the above exception, another exception occurred:

Traceback (most recent call last):
  File "D:\henry2\vemo\ve_vemo\lib\site-packages\django\template\base.py", line 907, in _resolve_lookup
    (bit, current))  # missing attribute
django.template.base.VariableDoesNotExist: Failed lookup for key [name] in "<RegexURLResolver <module 'oauth2_provider.urls' from 'D:\\\\henry2\\\\vemo\\\\ve_vemo\\\\lib\\\\site-packages\\\\oauth2_provider\\\\urls.py'> (None:oauth2_provider) ^o/>"
[2016-11-17 16:37:07] DEBUG [django.template:929] Exception while resolving variable 'name' in template 'unknown'.
Traceback (most recent call last):
  File "D:\henry2\vemo\ve_vemo\lib\site-packages\django\core\handlers\exception.py", line 39, in inner
    response = get_response(request)
  File "D:\henry2\vemo\ve_vemo\lib\site-packages\django\core\handlers\base.py", line 172, in _get_response
    resolver_match = resolver.resolve(request.path_info)
  File "D:\henry2\vemo\ve_vemo\lib\site-packages\django\urls\resolvers.py", line 300, in resolve
    raise Resolver404({'tried': tried, 'path': new_path})
django.urls.exceptions.Resolver404: {'tried': [[<RegexURLResolver <RegexURLPattern list> (admin:admin) ^admin/>], [<RegexURLResolver <module 'django.contrib.admindocs.urls' from 'D:\\henry2\\vemo\\ve_vemo\\lib\\site-packages\\django\\contrib\\admindocs\\urls.py'> (None:None) ^admin/doc/>], [<RegexURLResolver <module 'rest_framework.urls' from 'D:\\henry2\\vemo\\ve_vemo\\lib\\site-packages\\rest_framework\\urls.py'> (rest_framework:rest_framework) ^api-auth/>], [<RegexURLResolver <module 'oauth2_provider.urls' from 'D:\\henry2\\vemo\\ve_vemo\\lib\\site-packages\\oauth2_provider\\urls.py'> (None:oauth2_provider) ^o/>], [<RegexURLResolver <module 'vemo_service_apps.auths_api.urls' from 'D:\\henry2\\vemo\\vemo_service\\vemo_service_apps\\auths_api\\urls.py'> (None:None) ^api/auths/>], [<RegexURLResolver <module 'vemo_service_apps.catalogo_api.urls' from 'D:\\henry2\\vemo\\vemo_service\\vemo_service_apps\\catalogo_api\\urls.py'> (None:None) ^api/catalogo/>]], 'path': 'favicon.ico'}

During handling of the above exception, another exception occurred:

Traceback (most recent call last):
  File "D:\henry2\vemo\ve_vemo\lib\site-packages\django\template\base.py", line 885, in _resolve_lookup
    current = current[bit]
TypeError: 'RegexURLResolver' object is not subscriptable

During handling of the above exception, another exception occurred:

Traceback (most recent call last):
  File "D:\henry2\vemo\ve_vemo\lib\site-packages\django\template\base.py", line 893, in _resolve_lookup
    current = getattr(current, bit)
AttributeError: 'RegexURLResolver' object has no attribute 'name'

During handling of the above exception, another exception occurred:

Traceback (most recent call last):
  File "D:\henry2\vemo\ve_vemo\lib\site-packages\django\template\base.py", line 900, in _resolve_lookup
    current = current[int(bit)]
ValueError: invalid literal for int() with base 10: 'name'

During handling of the above exception, another exception occurred:

Traceback (most recent call last):
  File "D:\henry2\vemo\ve_vemo\lib\site-packages\django\template\base.py", line 907, in _resolve_lookup
    (bit, current))  # missing attribute
django.template.base.VariableDoesNotExist: Failed lookup for key [name] in "<RegexURLResolver <module 'oauth2_provider.urls' from 'D:\\\\henry2\\\\vemo\\\\ve_vemo\\\\lib\\\\site-packages\\\\oauth2_provider\\\\urls.py'> (None:oauth2_provider) ^o/>"
[2016-11-17 16:37:07] DEBUG [django.template:929] Exception while resolving variable 'name' in template 'unknown'.
Traceback (most recent call last):
  File "D:\henry2\vemo\ve_vemo\lib\site-packages\django\core\handlers\exception.py", line 39, in inner
    response = get_response(request)
  File "D:\henry2\vemo\ve_vemo\lib\site-packages\django\core\handlers\base.py", line 172, in _get_response
    resolver_match = resolver.resolve(request.path_info)
  File "D:\henry2\vemo\ve_vemo\lib\site-packages\django\urls\resolvers.py", line 300, in resolve
    raise Resolver404({'tried': tried, 'path': new_path})
django.urls.exceptions.Resolver404: {'tried': [[<RegexURLResolver <RegexURLPattern list> (admin:admin) ^admin/>], [<RegexURLResolver <module 'django.contrib.admindocs.urls' from 'D:\\henry2\\vemo\\ve_vemo\\lib\\site-packages\\django\\contrib\\admindocs\\urls.py'> (None:None) ^admin/doc/>], [<RegexURLResolver <module 'rest_framework.urls' from 'D:\\henry2\\vemo\\ve_vemo\\lib\\site-packages\\rest_framework\\urls.py'> (rest_framework:rest_framework) ^api-auth/>], [<RegexURLResolver <module 'oauth2_provider.urls' from 'D:\\henry2\\vemo\\ve_vemo\\lib\\site-packages\\oauth2_provider\\urls.py'> (None:oauth2_provider) ^o/>], [<RegexURLResolver <module 'vemo_service_apps.auths_api.urls' from 'D:\\henry2\\vemo\\vemo_service\\vemo_service_apps\\auths_api\\urls.py'> (None:None) ^api/auths/>], [<RegexURLResolver <module 'vemo_service_apps.catalogo_api.urls' from 'D:\\henry2\\vemo\\vemo_service\\vemo_service_apps\\catalogo_api\\urls.py'> (None:None) ^api/catalogo/>]], 'path': 'favicon.ico'}

During handling of the above exception, another exception occurred:

Traceback (most recent call last):
  File "D:\henry2\vemo\ve_vemo\lib\site-packages\django\template\base.py", line 885, in _resolve_lookup
    current = current[bit]
TypeError: 'RegexURLResolver' object is not subscriptable

During handling of the above exception, another exception occurred:

Traceback (most recent call last):
  File "D:\henry2\vemo\ve_vemo\lib\site-packages\django\template\base.py", line 893, in _resolve_lookup
    current = getattr(current, bit)
AttributeError: 'RegexURLResolver' object has no attribute 'name'

During handling of the above exception, another exception occurred:

Traceback (most recent call last):
  File "D:\henry2\vemo\ve_vemo\lib\site-packages\django\template\base.py", line 900, in _resolve_lookup
    current = current[int(bit)]
ValueError: invalid literal for int() with base 10: 'name'

During handling of the above exception, another exception occurred:

Traceback (most recent call last):
  File "D:\henry2\vemo\ve_vemo\lib\site-packages\django\template\base.py", line 907, in _resolve_lookup
    (bit, current))  # missing attribute
django.template.base.VariableDoesNotExist: Failed lookup for key [name] in "<RegexURLResolver <module 'vemo_service_apps.auths_api.urls' from 'D:\\\\henry2\\\\vemo\\\\vemo_service\\\\vemo_service_apps\\\\auths_api\\\\urls.py'> (None:None) ^api/auths/>"
[2016-11-17 16:37:07] DEBUG [django.template:929] Exception while resolving variable 'name' in template 'unknown'.
Traceback (most recent call last):
  File "D:\henry2\vemo\ve_vemo\lib\site-packages\django\core\handlers\exception.py", line 39, in inner
    response = get_response(request)
  File "D:\henry2\vemo\ve_vemo\lib\site-packages\django\core\handlers\base.py", line 172, in _get_response
    resolver_match = resolver.resolve(request.path_info)
  File "D:\henry2\vemo\ve_vemo\lib\site-packages\django\urls\resolvers.py", line 300, in resolve
    raise Resolver404({'tried': tried, 'path': new_path})
django.urls.exceptions.Resolver404: {'tried': [[<RegexURLResolver <RegexURLPattern list> (admin:admin) ^admin/>], [<RegexURLResolver <module 'django.contrib.admindocs.urls' from 'D:\\henry2\\vemo\\ve_vemo\\lib\\site-packages\\django\\contrib\\admindocs\\urls.py'> (None:None) ^admin/doc/>], [<RegexURLResolver <module 'rest_framework.urls' from 'D:\\henry2\\vemo\\ve_vemo\\lib\\site-packages\\rest_framework\\urls.py'> (rest_framework:rest_framework) ^api-auth/>], [<RegexURLResolver <module 'oauth2_provider.urls' from 'D:\\henry2\\vemo\\ve_vemo\\lib\\site-packages\\oauth2_provider\\urls.py'> (None:oauth2_provider) ^o/>], [<RegexURLResolver <module 'vemo_service_apps.auths_api.urls' from 'D:\\henry2\\vemo\\vemo_service\\vemo_service_apps\\auths_api\\urls.py'> (None:None) ^api/auths/>], [<RegexURLResolver <module 'vemo_service_apps.catalogo_api.urls' from 'D:\\henry2\\vemo\\vemo_service\\vemo_service_apps\\catalogo_api\\urls.py'> (None:None) ^api/catalogo/>]], 'path': 'favicon.ico'}

During handling of the above exception, another exception occurred:

Traceback (most recent call last):
  File "D:\henry2\vemo\ve_vemo\lib\site-packages\django\template\base.py", line 885, in _resolve_lookup
    current = current[bit]
TypeError: 'RegexURLResolver' object is not subscriptable

During handling of the above exception, another exception occurred:

Traceback (most recent call last):
  File "D:\henry2\vemo\ve_vemo\lib\site-packages\django\template\base.py", line 893, in _resolve_lookup
    current = getattr(current, bit)
AttributeError: 'RegexURLResolver' object has no attribute 'name'

During handling of the above exception, another exception occurred:

Traceback (most recent call last):
  File "D:\henry2\vemo\ve_vemo\lib\site-packages\django\template\base.py", line 900, in _resolve_lookup
    current = current[int(bit)]
ValueError: invalid literal for int() with base 10: 'name'

During handling of the above exception, another exception occurred:

Traceback (most recent call last):
  File "D:\henry2\vemo\ve_vemo\lib\site-packages\django\template\base.py", line 907, in _resolve_lookup
    (bit, current))  # missing attribute
django.template.base.VariableDoesNotExist: Failed lookup for key [name] in "<RegexURLResolver <module 'vemo_service_apps.auths_api.urls' from 'D:\\\\henry2\\\\vemo\\\\vemo_service\\\\vemo_service_apps\\\\auths_api\\\\urls.py'> (None:None) ^api/auths/>"
[2016-11-17 16:37:07] DEBUG [django.template:929] Exception while resolving variable 'name' in template 'unknown'.
Traceback (most recent call last):
  File "D:\henry2\vemo\ve_vemo\lib\site-packages\django\core\handlers\exception.py", line 39, in inner
    response = get_response(request)
  File "D:\henry2\vemo\ve_vemo\lib\site-packages\django\core\handlers\base.py", line 172, in _get_response
    resolver_match = resolver.resolve(request.path_info)
  File "D:\henry2\vemo\ve_vemo\lib\site-packages\django\urls\resolvers.py", line 300, in resolve
    raise Resolver404({'tried': tried, 'path': new_path})
django.urls.exceptions.Resolver404: {'tried': [[<RegexURLResolver <RegexURLPattern list> (admin:admin) ^admin/>], [<RegexURLResolver <module 'django.contrib.admindocs.urls' from 'D:\\henry2\\vemo\\ve_vemo\\lib\\site-packages\\django\\contrib\\admindocs\\urls.py'> (None:None) ^admin/doc/>], [<RegexURLResolver <module 'rest_framework.urls' from 'D:\\henry2\\vemo\\ve_vemo\\lib\\site-packages\\rest_framework\\urls.py'> (rest_framework:rest_framework) ^api-auth/>], [<RegexURLResolver <module 'oauth2_provider.urls' from 'D:\\henry2\\vemo\\ve_vemo\\lib\\site-packages\\oauth2_provider\\urls.py'> (None:oauth2_provider) ^o/>], [<RegexURLResolver <module 'vemo_service_apps.auths_api.urls' from 'D:\\henry2\\vemo\\vemo_service\\vemo_service_apps\\auths_api\\urls.py'> (None:None) ^api/auths/>], [<RegexURLResolver <module 'vemo_service_apps.catalogo_api.urls' from 'D:\\henry2\\vemo\\vemo_service\\vemo_service_apps\\catalogo_api\\urls.py'> (None:None) ^api/catalogo/>]], 'path': 'favicon.ico'}

During handling of the above exception, another exception occurred:

Traceback (most recent call last):
  File "D:\henry2\vemo\ve_vemo\lib\site-packages\django\template\base.py", line 885, in _resolve_lookup
    current = current[bit]
TypeError: 'RegexURLResolver' object is not subscriptable

During handling of the above exception, another exception occurred:

Traceback (most recent call last):
  File "D:\henry2\vemo\ve_vemo\lib\site-packages\django\template\base.py", line 893, in _resolve_lookup
    current = getattr(current, bit)
AttributeError: 'RegexURLResolver' object has no attribute 'name'

During handling of the above exception, another exception occurred:

Traceback (most recent call last):
  File "D:\henry2\vemo\ve_vemo\lib\site-packages\django\template\base.py", line 900, in _resolve_lookup
    current = current[int(bit)]
ValueError: invalid literal for int() with base 10: 'name'

During handling of the above exception, another exception occurred:

Traceback (most recent call last):
  File "D:\henry2\vemo\ve_vemo\lib\site-packages\django\template\base.py", line 907, in _resolve_lookup
    (bit, current))  # missing attribute
django.template.base.VariableDoesNotExist: Failed lookup for key [name] in "<RegexURLResolver <module 'vemo_service_apps.catalogo_api.urls' from 'D:\\\\henry2\\\\vemo\\\\vemo_service\\\\vemo_service_apps\\\\catalogo_api\\\\urls.py'> (None:None) ^api/catalogo/>"
[2016-11-17 16:37:07] DEBUG [django.template:929] Exception while resolving variable 'name' in template 'unknown'.
Traceback (most recent call last):
  File "D:\henry2\vemo\ve_vemo\lib\site-packages\django\core\handlers\exception.py", line 39, in inner
    response = get_response(request)
  File "D:\henry2\vemo\ve_vemo\lib\site-packages\django\core\handlers\base.py", line 172, in _get_response
    resolver_match = resolver.resolve(request.path_info)
  File "D:\henry2\vemo\ve_vemo\lib\site-packages\django\urls\resolvers.py", line 300, in resolve
    raise Resolver404({'tried': tried, 'path': new_path})
django.urls.exceptions.Resolver404: {'tried': [[<RegexURLResolver <RegexURLPattern list> (admin:admin) ^admin/>], [<RegexURLResolver <module 'django.contrib.admindocs.urls' from 'D:\\henry2\\vemo\\ve_vemo\\lib\\site-packages\\django\\contrib\\admindocs\\urls.py'> (None:None) ^admin/doc/>], [<RegexURLResolver <module 'rest_framework.urls' from 'D:\\henry2\\vemo\\ve_vemo\\lib\\site-packages\\rest_framework\\urls.py'> (rest_framework:rest_framework) ^api-auth/>], [<RegexURLResolver <module 'oauth2_provider.urls' from 'D:\\henry2\\vemo\\ve_vemo\\lib\\site-packages\\oauth2_provider\\urls.py'> (None:oauth2_provider) ^o/>], [<RegexURLResolver <module 'vemo_service_apps.auths_api.urls' from 'D:\\henry2\\vemo\\vemo_service\\vemo_service_apps\\auths_api\\urls.py'> (None:None) ^api/auths/>], [<RegexURLResolver <module 'vemo_service_apps.catalogo_api.urls' from 'D:\\henry2\\vemo\\vemo_service\\vemo_service_apps\\catalogo_api\\urls.py'> (None:None) ^api/catalogo/>]], 'path': 'favicon.ico'}

During handling of the above exception, another exception occurred:

Traceback (most recent call last):
  File "D:\henry2\vemo\ve_vemo\lib\site-packages\django\template\base.py", line 885, in _resolve_lookup
    current = current[bit]
TypeError: 'RegexURLResolver' object is not subscriptable

During handling of the above exception, another exception occurred:

Traceback (most recent call last):
  File "D:\henry2\vemo\ve_vemo\lib\site-packages\django\template\base.py", line 893, in _resolve_lookup
    current = getattr(current, bit)
AttributeError: 'RegexURLResolver' object has no attribute 'name'

During handling of the above exception, another exception occurred:

Traceback (most recent call last):
  File "D:\henry2\vemo\ve_vemo\lib\site-packages\django\template\base.py", line 900, in _resolve_lookup
    current = current[int(bit)]
ValueError: invalid literal for int() with base 10: 'name'

During handling of the above exception, another exception occurred:

Traceback (most recent call last):
  File "D:\henry2\vemo\ve_vemo\lib\site-packages\django\template\base.py", line 907, in _resolve_lookup
    (bit, current))  # missing attribute
django.template.base.VariableDoesNotExist: Failed lookup for key [name] in "<RegexURLResolver <module 'vemo_service_apps.catalogo_api.urls' from 'D:\\\\henry2\\\\vemo\\\\vemo_service\\\\vemo_service_apps\\\\catalogo_api\\\\urls.py'> (None:None) ^api/catalogo/>"
[2016-11-17 16:37:07] WARNING [django.request:152] Not Found: /favicon.ico
[2016-11-17 16:37:07] WARNING [django.request:152] Not Found: /favicon.ico
[2016-11-17 16:37:07] WARNING [django.server:131] "GET /favicon.ico HTTP/1.1" 404 2488
[2016-11-17 16:37:07] WARNING [django.server:131] "GET /favicon.ico HTTP/1.1" 404 2488
[2016-11-17 16:37:19] DEBUG [django.db.backends:90] (0.001) SELECT "django_session"."session_key", "django_session"."session_data", "django_session"."expire_date" FROM "django_session" WHERE ("django_session"."expire_date" > '2016-11-17 21:37:19.632857' AND "django_session"."session_key" = 'jtam21hl0n0xr7ua1d3sc827zbz8btzy'); args=('2016-11-17 21:37:19.632857', 'jtam21hl0n0xr7ua1d3sc827zbz8btzy')
[2016-11-17 16:37:19] DEBUG [django.db.backends:90] (0.000) SELECT "auths_user"."password", "auths_user"."last_login", "auths_user"."is_superuser", "auths_user"."username", "auths_user"."first_name", "auths_user"."last_name", "auths_user"."email", "auths_user"."is_staff", "auths_user"."is_active", "auths_user"."date_joined", "auths_user"."id", "auths_user"."last_hierarchy_id", "auths_user"."last_module_id", "auths_user"."person_id", "auths_user"."updated_at", "auths_user"."registered_by" FROM "auths_user" WHERE "auths_user"."id" = '3651942c1384420da02bbf9e5eca3faa'; args=('3651942c1384420da02bbf9e5eca3faa',)
[2016-11-17 16:37:19] DEBUG [django.template:929] Exception while resolving variable 'is_popup' in template 'admin/index.html'.
Traceback (most recent call last):
  File "D:\henry2\vemo\ve_vemo\lib\site-packages\django\template\base.py", line 885, in _resolve_lookup
    current = current[bit]
  File "D:\henry2\vemo\ve_vemo\lib\site-packages\django\template\context.py", line 75, in __getitem__
    raise KeyError(key)
KeyError: 'is_popup'

During handling of the above exception, another exception occurred:

Traceback (most recent call last):
  File "D:\henry2\vemo\ve_vemo\lib\site-packages\django\template\base.py", line 891, in _resolve_lookup
    if isinstance(current, BaseContext) and getattr(type(current), bit):
AttributeError: type object 'RequestContext' has no attribute 'is_popup'

During handling of the above exception, another exception occurred:

Traceback (most recent call last):
  File "D:\henry2\vemo\ve_vemo\lib\site-packages\django\template\base.py", line 900, in _resolve_lookup
    current = current[int(bit)]
ValueError: invalid literal for int() with base 10: 'is_popup'

During handling of the above exception, another exception occurred:

Traceback (most recent call last):
  File "D:\henry2\vemo\ve_vemo\lib\site-packages\django\template\base.py", line 907, in _resolve_lookup
    (bit, current))  # missing attribute
django.template.base.VariableDoesNotExist: Failed lookup for key [is_popup] in "[{'False': False, 'True': True, 'None': None}, {'DEFAULT_MESSAGE_LEVELS': {'SUCCESS': 25, 'ERROR': 40, 'INFO': 20, 'DEBUG': 10, 'WARNING': 30}, 'csrf_token': <SimpleLazyObject: <function csrf.<locals>._get_val at 0x03C62D68>>, 'user': <SimpleLazyObject: <User: admin>>, 'perms': <django.contrib.auth.context_processors.PermWrapper object at 0x03FE07F0>, 'messages': <django.contrib.messages.storage.fallback.FallbackStorage object at 0x03F5C910>, 'request': <WSGIRequest: GET '/admin/'>}, {}, {'LANGUAGE_CODE': 'en-us', 'site_header': <django.utils.functional.lazy.<locals>.__proxy__ object at 0x02F9EBF0>, 'available_apps': [{'has_module_perms': True, 'app_label': 'auth', 'models': [{'perms': {'add': True, 'change': True, 'delete': True}, 'admin_url': '/admin/auth/group/', 'add_url': '/admin/auth/group/add/', 'object_name': 'Group', 'name': <django.utils.functional.lazy.<locals>.__proxy__ object at 0x03F90AF0>}, {'perms': {'add': True, 'change': True, 'delete': True}, 'admin_url': '/admin/auth/permission/', 'add_url': '/admin/auth/permission/add/', 'object_name': 'Permission', 'name': <django.utils.functional.lazy.<locals>.__proxy__ object at 0x03F90550>}], 'app_url': '/admin/auth/', 'name': <django.utils.functional.lazy.<locals>.__proxy__ object at 0x02FB2670>}, {'has_module_perms': True, 'app_label': 'auths', 'models': [{'perms': {'add': True, 'change': True, 'delete': True}, 'admin_url': '/admin/auths/hierarchytype/', 'add_url': '/admin/auths/hierarchytype/add/', 'object_name': 'HierarchyType', 'name': <django.utils.functional.lazy.<locals>.__proxy__ object at 0x03F900D0>}, {'perms': {'add': True, 'change': True, 'delete': True}, 'admin_url': '/admin/auths/hierarchy/', 'add_url': '/admin/auths/hierarchy/add/', 'object_name': 'Hierarchy', 'name': <django.utils.functional.lazy.<locals>.__proxy__ object at 0x03F90A90>}, {'perms': {'add': True, 'change': True, 'delete': True}, 'admin_url': '/admin/auths/menu/', 'add_url': '/admin/auths/menu/add/', 'object_name': 'Menu', 'name': <django.utils.functional.lazy.<locals>.__proxy__ object at 0x03F90690>}, {'perms': {'add': True, 'change': True, 'delete': True}, 'admin_url': '/admin/auths/person/', 'add_url': '/admin/auths/person/add/', 'object_name': 'Person', 'name': <django.utils.functional.lazy.<locals>.__proxy__ object at 0x03F90150>}, {'perms': {'add': True, 'change': True, 'delete': True}, 'admin_url': '/admin/auths/userhierarchygroup/', 'add_url': '/admin/auths/userhierarchygroup/add/', 'object_name': 'UserHierarchyGroup', 'name': <django.utils.functional.lazy.<locals>.__proxy__ object at 0x03F90AD0>}, {'perms': {'add': True, 'change': True, 'delete': True}, 'admin_url': '/admin/auths/userhierarchypermission/', 'add_url': '/admin/auths/userhierarchypermission/add/', 'object_name': 'UserHierarchyPermission', 'name': <django.utils.functional.lazy.<locals>.__proxy__ object at 0x03F90730>}, {'perms': {'add': True, 'change': True, 'delete': True}, 'admin_url': '/admin/auths/user/', 'add_url': '/admin/auths/user/add/', 'object_name': 'User', 'name': <django.utils.functional.lazy.<locals>.__proxy__ object at 0x03F902B0>}], 'app_url': '/admin/auths/', 'name': 'Auths'}, {'has_module_perms': True, 'app_label': 'catalogo', 'models': [{'perms': {'add': True, 'change': True, 'delete': True}, 'admin_url': '/admin/catalogo/autor/', 'add_url': '/admin/catalogo/autor/add/', 'object_name': 'Autor', 'name': 'Autores'}, {'perms': {'add': True, 'change': True, 'delete': True}, 'admin_url': '/admin/catalogo/categoria/', 'add_url': '/admin/catalogo/categoria/add/', 'object_name': 'Categoria', 'name': 'Categorias'}, {'perms': {'add': True, 'change': True, 'delete': True}, 'admin_url': '/admin/catalogo/libro/', 'add_url': '/admin/catalogo/libro/add/', 'object_name': 'Libro', 'name': 'Libros'}], 'app_url': '/admin/catalogo/', 'name': 'Catalogo'}, {'has_module_perms': True, 'app_label': 'contenttypes', 'models': [{'perms': {'add': True, 'change': True, 'delete': True}, 'admin_url': '/admin/contenttypes/contenttype/', 'add_url': '/admin/contenttypes/contenttype/add/', 'object_name': 'ContentType', 'name': <django.utils.functional.lazy.<locals>.__proxy__ object at 0x03F902F0>}], 'app_url': '/admin/contenttypes/', 'name': <django.utils.functional.lazy.<locals>.__proxy__ object at 0x02FB27B0>}, {'has_module_perms': True, 'app_label': 'oauth2_provider', 'models': [{'perms': {'add': True, 'change': True, 'delete': True}, 'admin_url': '/admin/oauth2_provider/accesstoken/', 'add_url': '/admin/oauth2_provider/accesstoken/add/', 'object_name': 'AccessToken', 'name': <django.utils.functional.lazy.<locals>.__proxy__ object at 0x03F90750>}, {'perms': {'add': True, 'change': True, 'delete': True}, 'admin_url': '/admin/oauth2_provider/application/', 'add_url': '/admin/oauth2_provider/application/add/', 'object_name': 'Application', 'name': <django.utils.functional.lazy.<locals>.__proxy__ object at 0x03F900F0>}, {'perms': {'add': True, 'change': True, 'delete': True}, 'admin_url': '/admin/oauth2_provider/grant/', 'add_url': '/admin/oauth2_provider/grant/add/', 'object_name': 'Grant', 'name': <django.utils.functional.lazy.<locals>.__proxy__ object at 0x03F90330>}, {'perms': {'add': True, 'change': True, 'delete': True}, 'admin_url': '/admin/oauth2_provider/refreshtoken/', 'add_url': '/admin/oauth2_provider/refreshtoken/add/', 'object_name': 'RefreshToken', 'name': <django.utils.functional.lazy.<locals>.__proxy__ object at 0x03F90A50>}], 'app_url': '/admin/oauth2_provider/', 'name': 'Django OAuth Toolkit'}], 'site_url': '/', 'title': <django.utils.functional.lazy.<locals>.__proxy__ object at 0x02F9EC50>, 'LANGUAGE_BIDI': False, 'has_permission': True, 'app_list': [{'has_module_perms': True, 'app_label': 'auth', 'models': [{'perms': {'add': True, 'change': True, 'delete': True}, 'admin_url': '/admin/auth/group/', 'add_url': '/admin/auth/group/add/', 'object_name': 'Group', 'name': <django.utils.functional.lazy.<locals>.__proxy__ object at 0x03F5CE50>}, {'perms': {'add': True, 'change': True, 'delete': True}, 'admin_url': '/admin/auth/permission/', 'add_url': '/admin/auth/permission/add/', 'object_name': 'Permission', 'name': <django.utils.functional.lazy.<locals>.__proxy__ object at 0x039123B0>}], 'app_url': '/admin/auth/', 'name': <django.utils.functional.lazy.<locals>.__proxy__ object at 0x02FB2670>}, {'has_module_perms': True, 'app_label': 'auths', 'models': [{'perms': {'add': True, 'change': True, 'delete': True}, 'admin_url': '/admin/auths/hierarchytype/', 'add_url': '/admin/auths/hierarchytype/add/', 'object_name': 'HierarchyType', 'name': <django.utils.functional.lazy.<locals>.__proxy__ object at 0x03912270>}, {'perms': {'add': True, 'change': True, 'delete': True}, 'admin_url': '/admin/auths/hierarchy/', 'add_url': '/admin/auths/hierarchy/add/', 'object_name': 'Hierarchy', 'name': <django.utils.functional.lazy.<locals>.__proxy__ object at 0x03AE4530>}, {'perms': {'add': True, 'change': True, 'delete': True}, 'admin_url': '/admin/auths/menu/', 'add_url': '/admin/auths/menu/add/', 'object_name': 'Menu', 'name': <django.utils.functional.lazy.<locals>.__proxy__ object at 0x03F5CE30>}, {'perms': {'add': True, 'change': True, 'delete': True}, 'admin_url': '/admin/auths/person/', 'add_url': '/admin/auths/person/add/', 'object_name': 'Person', 'name': <django.utils.functional.lazy.<locals>.__proxy__ object at 0x03912630>}, {'perms': {'add': True, 'change': True, 'delete': True}, 'admin_url': '/admin/auths/userhierarchygroup/', 'add_url': '/admin/auths/userhierarchygroup/add/', 'object_name': 'UserHierarchyGroup', 'name': <django.utils.functional.lazy.<locals>.__proxy__ object at 0x03F90890>}, {'perms': {'add': True, 'change': True, 'delete': True}, 'admin_url': '/admin/auths/userhierarchypermission/', 'add_url': '/admin/auths/userhierarchypermission/add/', 'object_name': 'UserHierarchyPermission', 'name': <django.utils.functional.lazy.<locals>.__proxy__ object at 0x03AE4470>}, {'perms': {'add': True, 'change': True, 'delete': True}, 'admin_url': '/admin/auths/user/', 'add_url': '/admin/auths/user/add/', 'object_name': 'User', 'name': <django.utils.functional.lazy.<locals>.__proxy__ object at 0x03AE44F0>}], 'app_url': '/admin/auths/', 'name': 'Auths'}, {'has_module_perms': True, 'app_label': 'catalogo', 'models': [{'perms': {'add': True, 'change': True, 'delete': True}, 'admin_url': '/admin/catalogo/autor/', 'add_url': '/admin/catalogo/autor/add/', 'object_name': 'Autor', 'name': 'Autores'}, {'perms': {'add': True, 'change': True, 'delete': True}, 'admin_url': '/admin/catalogo/categoria/', 'add_url': '/admin/catalogo/categoria/add/', 'object_name': 'Categoria', 'name': 'Categorias'}, {'perms': {'add': True, 'change': True, 'delete': True}, 'admin_url': '/admin/catalogo/libro/', 'add_url': '/admin/catalogo/libro/add/', 'object_name': 'Libro', 'name': 'Libros'}], 'app_url': '/admin/catalogo/', 'name': 'Catalogo'}, {'has_module_perms': True, 'app_label': 'contenttypes', 'models': [{'perms': {'add': True, 'change': True, 'delete': True}, 'admin_url': '/admin/contenttypes/contenttype/', 'add_url': '/admin/contenttypes/contenttype/add/', 'object_name': 'ContentType', 'name': <django.utils.functional.lazy.<locals>.__proxy__ object at 0x03F908B0>}], 'app_url': '/admin/contenttypes/', 'name': <django.utils.functional.lazy.<locals>.__proxy__ object at 0x02FB27B0>}, {'has_module_perms': True, 'app_label': 'oauth2_provider', 'models': [{'perms': {'add': True, 'change': True, 'delete': True}, 'admin_url': '/admin/oauth2_provider/accesstoken/', 'add_url': '/admin/oauth2_provider/accesstoken/add/', 'object_name': 'AccessToken', 'name': <django.utils.functional.lazy.<locals>.__proxy__ object at 0x039122F0>}, {'perms': {'add': True, 'change': True, 'delete': True}, 'admin_url': '/admin/oauth2_provider/application/', 'add_url': '/admin/oauth2_provider/application/add/', 'object_name': 'Application', 'name': <django.utils.functional.lazy.<locals>.__proxy__ object at 0x039123F0>}, {'perms': {'add': True, 'change': True, 'delete': True}, 'admin_url': '/admin/oauth2_provider/grant/', 'add_url': '/admin/oauth2_provider/grant/add/', 'object_name': 'Grant', 'name': <django.utils.functional.lazy.<locals>.__proxy__ object at 0x03912070>}, {'perms': {'add': True, 'change': True, 'delete': True}, 'admin_url': '/admin/oauth2_provider/refreshtoken/', 'add_url': '/admin/oauth2_provider/refreshtoken/add/', 'object_name': 'RefreshToken', 'name': <django.utils.functional.lazy.<locals>.__proxy__ object at 0x03ADA7B0>}], 'app_url': '/admin/oauth2_provider/', 'name': 'Django OAuth Toolkit'}], 'site_title': <django.utils.functional.lazy.<locals>.__proxy__ object at 0x02F9EB90>}]"
[2016-11-17 16:37:19] DEBUG [django.template:929] Exception while resolving variable 'is_popup' in template 'admin/index.html'.
Traceback (most recent call last):
  File "D:\henry2\vemo\ve_vemo\lib\site-packages\django\template\base.py", line 885, in _resolve_lookup
    current = current[bit]
  File "D:\henry2\vemo\ve_vemo\lib\site-packages\django\template\context.py", line 75, in __getitem__
    raise KeyError(key)
KeyError: 'is_popup'

During handling of the above exception, another exception occurred:

Traceback (most recent call last):
  File "D:\henry2\vemo\ve_vemo\lib\site-packages\django\template\base.py", line 891, in _resolve_lookup
    if isinstance(current, BaseContext) and getattr(type(current), bit):
AttributeError: type object 'RequestContext' has no attribute 'is_popup'

During handling of the above exception, another exception occurred:

Traceback (most recent call last):
  File "D:\henry2\vemo\ve_vemo\lib\site-packages\django\template\base.py", line 900, in _resolve_lookup
    current = current[int(bit)]
ValueError: invalid literal for int() with base 10: 'is_popup'

During handling of the above exception, another exception occurred:

Traceback (most recent call last):
  File "D:\henry2\vemo\ve_vemo\lib\site-packages\django\template\base.py", line 907, in _resolve_lookup
    (bit, current))  # missing attribute
django.template.base.VariableDoesNotExist: Failed lookup for key [is_popup] in "[{'False': False, 'True': True, 'None': None}, {'DEFAULT_MESSAGE_LEVELS': {'SUCCESS': 25, 'ERROR': 40, 'INFO': 20, 'DEBUG': 10, 'WARNING': 30}, 'csrf_token': <SimpleLazyObject: <function csrf.<locals>._get_val at 0x03C62D68>>, 'user': <SimpleLazyObject: <User: admin>>, 'perms': <django.contrib.auth.context_processors.PermWrapper object at 0x03FE07F0>, 'messages': <django.contrib.messages.storage.fallback.FallbackStorage object at 0x03F5C910>, 'request': <WSGIRequest: GET '/admin/'>}, {}, {'LANGUAGE_CODE': 'en-us', 'site_header': <django.utils.functional.lazy.<locals>.__proxy__ object at 0x02F9EBF0>, 'available_apps': [{'has_module_perms': True, 'app_label': 'auth', 'models': [{'perms': {'add': True, 'change': True, 'delete': True}, 'admin_url': '/admin/auth/group/', 'add_url': '/admin/auth/group/add/', 'object_name': 'Group', 'name': <django.utils.functional.lazy.<locals>.__proxy__ object at 0x03F90AF0>}, {'perms': {'add': True, 'change': True, 'delete': True}, 'admin_url': '/admin/auth/permission/', 'add_url': '/admin/auth/permission/add/', 'object_name': 'Permission', 'name': <django.utils.functional.lazy.<locals>.__proxy__ object at 0x03F90550>}], 'app_url': '/admin/auth/', 'name': <django.utils.functional.lazy.<locals>.__proxy__ object at 0x02FB2670>}, {'has_module_perms': True, 'app_label': 'auths', 'models': [{'perms': {'add': True, 'change': True, 'delete': True}, 'admin_url': '/admin/auths/hierarchytype/', 'add_url': '/admin/auths/hierarchytype/add/', 'object_name': 'HierarchyType', 'name': <django.utils.functional.lazy.<locals>.__proxy__ object at 0x03F900D0>}, {'perms': {'add': True, 'change': True, 'delete': True}, 'admin_url': '/admin/auths/hierarchy/', 'add_url': '/admin/auths/hierarchy/add/', 'object_name': 'Hierarchy', 'name': <django.utils.functional.lazy.<locals>.__proxy__ object at 0x03F90A90>}, {'perms': {'add': True, 'change': True, 'delete': True}, 'admin_url': '/admin/auths/menu/', 'add_url': '/admin/auths/menu/add/', 'object_name': 'Menu', 'name': <django.utils.functional.lazy.<locals>.__proxy__ object at 0x03F90690>}, {'perms': {'add': True, 'change': True, 'delete': True}, 'admin_url': '/admin/auths/person/', 'add_url': '/admin/auths/person/add/', 'object_name': 'Person', 'name': <django.utils.functional.lazy.<locals>.__proxy__ object at 0x03F90150>}, {'perms': {'add': True, 'change': True, 'delete': True}, 'admin_url': '/admin/auths/userhierarchygroup/', 'add_url': '/admin/auths/userhierarchygroup/add/', 'object_name': 'UserHierarchyGroup', 'name': <django.utils.functional.lazy.<locals>.__proxy__ object at 0x03F90AD0>}, {'perms': {'add': True, 'change': True, 'delete': True}, 'admin_url': '/admin/auths/userhierarchypermission/', 'add_url': '/admin/auths/userhierarchypermission/add/', 'object_name': 'UserHierarchyPermission', 'name': <django.utils.functional.lazy.<locals>.__proxy__ object at 0x03F90730>}, {'perms': {'add': True, 'change': True, 'delete': True}, 'admin_url': '/admin/auths/user/', 'add_url': '/admin/auths/user/add/', 'object_name': 'User', 'name': <django.utils.functional.lazy.<locals>.__proxy__ object at 0x03F902B0>}], 'app_url': '/admin/auths/', 'name': 'Auths'}, {'has_module_perms': True, 'app_label': 'catalogo', 'models': [{'perms': {'add': True, 'change': True, 'delete': True}, 'admin_url': '/admin/catalogo/autor/', 'add_url': '/admin/catalogo/autor/add/', 'object_name': 'Autor', 'name': 'Autores'}, {'perms': {'add': True, 'change': True, 'delete': True}, 'admin_url': '/admin/catalogo/categoria/', 'add_url': '/admin/catalogo/categoria/add/', 'object_name': 'Categoria', 'name': 'Categorias'}, {'perms': {'add': True, 'change': True, 'delete': True}, 'admin_url': '/admin/catalogo/libro/', 'add_url': '/admin/catalogo/libro/add/', 'object_name': 'Libro', 'name': 'Libros'}], 'app_url': '/admin/catalogo/', 'name': 'Catalogo'}, {'has_module_perms': True, 'app_label': 'contenttypes', 'models': [{'perms': {'add': True, 'change': True, 'delete': True}, 'admin_url': '/admin/contenttypes/contenttype/', 'add_url': '/admin/contenttypes/contenttype/add/', 'object_name': 'ContentType', 'name': <django.utils.functional.lazy.<locals>.__proxy__ object at 0x03F902F0>}], 'app_url': '/admin/contenttypes/', 'name': <django.utils.functional.lazy.<locals>.__proxy__ object at 0x02FB27B0>}, {'has_module_perms': True, 'app_label': 'oauth2_provider', 'models': [{'perms': {'add': True, 'change': True, 'delete': True}, 'admin_url': '/admin/oauth2_provider/accesstoken/', 'add_url': '/admin/oauth2_provider/accesstoken/add/', 'object_name': 'AccessToken', 'name': <django.utils.functional.lazy.<locals>.__proxy__ object at 0x03F90750>}, {'perms': {'add': True, 'change': True, 'delete': True}, 'admin_url': '/admin/oauth2_provider/application/', 'add_url': '/admin/oauth2_provider/application/add/', 'object_name': 'Application', 'name': <django.utils.functional.lazy.<locals>.__proxy__ object at 0x03F900F0>}, {'perms': {'add': True, 'change': True, 'delete': True}, 'admin_url': '/admin/oauth2_provider/grant/', 'add_url': '/admin/oauth2_provider/grant/add/', 'object_name': 'Grant', 'name': <django.utils.functional.lazy.<locals>.__proxy__ object at 0x03F90330>}, {'perms': {'add': True, 'change': True, 'delete': True}, 'admin_url': '/admin/oauth2_provider/refreshtoken/', 'add_url': '/admin/oauth2_provider/refreshtoken/add/', 'object_name': 'RefreshToken', 'name': <django.utils.functional.lazy.<locals>.__proxy__ object at 0x03F90A50>}], 'app_url': '/admin/oauth2_provider/', 'name': 'Django OAuth Toolkit'}], 'site_url': '/', 'title': <django.utils.functional.lazy.<locals>.__proxy__ object at 0x02F9EC50>, 'LANGUAGE_BIDI': False, 'has_permission': True, 'app_list': [{'has_module_perms': True, 'app_label': 'auth', 'models': [{'perms': {'add': True, 'change': True, 'delete': True}, 'admin_url': '/admin/auth/group/', 'add_url': '/admin/auth/group/add/', 'object_name': 'Group', 'name': <django.utils.functional.lazy.<locals>.__proxy__ object at 0x03F5CE50>}, {'perms': {'add': True, 'change': True, 'delete': True}, 'admin_url': '/admin/auth/permission/', 'add_url': '/admin/auth/permission/add/', 'object_name': 'Permission', 'name': <django.utils.functional.lazy.<locals>.__proxy__ object at 0x039123B0>}], 'app_url': '/admin/auth/', 'name': <django.utils.functional.lazy.<locals>.__proxy__ object at 0x02FB2670>}, {'has_module_perms': True, 'app_label': 'auths', 'models': [{'perms': {'add': True, 'change': True, 'delete': True}, 'admin_url': '/admin/auths/hierarchytype/', 'add_url': '/admin/auths/hierarchytype/add/', 'object_name': 'HierarchyType', 'name': <django.utils.functional.lazy.<locals>.__proxy__ object at 0x03912270>}, {'perms': {'add': True, 'change': True, 'delete': True}, 'admin_url': '/admin/auths/hierarchy/', 'add_url': '/admin/auths/hierarchy/add/', 'object_name': 'Hierarchy', 'name': <django.utils.functional.lazy.<locals>.__proxy__ object at 0x03AE4530>}, {'perms': {'add': True, 'change': True, 'delete': True}, 'admin_url': '/admin/auths/menu/', 'add_url': '/admin/auths/menu/add/', 'object_name': 'Menu', 'name': <django.utils.functional.lazy.<locals>.__proxy__ object at 0x03F5CE30>}, {'perms': {'add': True, 'change': True, 'delete': True}, 'admin_url': '/admin/auths/person/', 'add_url': '/admin/auths/person/add/', 'object_name': 'Person', 'name': <django.utils.functional.lazy.<locals>.__proxy__ object at 0x03912630>}, {'perms': {'add': True, 'change': True, 'delete': True}, 'admin_url': '/admin/auths/userhierarchygroup/', 'add_url': '/admin/auths/userhierarchygroup/add/', 'object_name': 'UserHierarchyGroup', 'name': <django.utils.functional.lazy.<locals>.__proxy__ object at 0x03F90890>}, {'perms': {'add': True, 'change': True, 'delete': True}, 'admin_url': '/admin/auths/userhierarchypermission/', 'add_url': '/admin/auths/userhierarchypermission/add/', 'object_name': 'UserHierarchyPermission', 'name': <django.utils.functional.lazy.<locals>.__proxy__ object at 0x03AE4470>}, {'perms': {'add': True, 'change': True, 'delete': True}, 'admin_url': '/admin/auths/user/', 'add_url': '/admin/auths/user/add/', 'object_name': 'User', 'name': <django.utils.functional.lazy.<locals>.__proxy__ object at 0x03AE44F0>}], 'app_url': '/admin/auths/', 'name': 'Auths'}, {'has_module_perms': True, 'app_label': 'catalogo', 'models': [{'perms': {'add': True, 'change': True, 'delete': True}, 'admin_url': '/admin/catalogo/autor/', 'add_url': '/admin/catalogo/autor/add/', 'object_name': 'Autor', 'name': 'Autores'}, {'perms': {'add': True, 'change': True, 'delete': True}, 'admin_url': '/admin/catalogo/categoria/', 'add_url': '/admin/catalogo/categoria/add/', 'object_name': 'Categoria', 'name': 'Categorias'}, {'perms': {'add': True, 'change': True, 'delete': True}, 'admin_url': '/admin/catalogo/libro/', 'add_url': '/admin/catalogo/libro/add/', 'object_name': 'Libro', 'name': 'Libros'}], 'app_url': '/admin/catalogo/', 'name': 'Catalogo'}, {'has_module_perms': True, 'app_label': 'contenttypes', 'models': [{'perms': {'add': True, 'change': True, 'delete': True}, 'admin_url': '/admin/contenttypes/contenttype/', 'add_url': '/admin/contenttypes/contenttype/add/', 'object_name': 'ContentType', 'name': <django.utils.functional.lazy.<locals>.__proxy__ object at 0x03F908B0>}], 'app_url': '/admin/contenttypes/', 'name': <django.utils.functional.lazy.<locals>.__proxy__ object at 0x02FB27B0>}, {'has_module_perms': True, 'app_label': 'oauth2_provider', 'models': [{'perms': {'add': True, 'change': True, 'delete': True}, 'admin_url': '/admin/oauth2_provider/accesstoken/', 'add_url': '/admin/oauth2_provider/accesstoken/add/', 'object_name': 'AccessToken', 'name': <django.utils.functional.lazy.<locals>.__proxy__ object at 0x039122F0>}, {'perms': {'add': True, 'change': True, 'delete': True}, 'admin_url': '/admin/oauth2_provider/application/', 'add_url': '/admin/oauth2_provider/application/add/', 'object_name': 'Application', 'name': <django.utils.functional.lazy.<locals>.__proxy__ object at 0x039123F0>}, {'perms': {'add': True, 'change': True, 'delete': True}, 'admin_url': '/admin/oauth2_provider/grant/', 'add_url': '/admin/oauth2_provider/grant/add/', 'object_name': 'Grant', 'name': <django.utils.functional.lazy.<locals>.__proxy__ object at 0x03912070>}, {'perms': {'add': True, 'change': True, 'delete': True}, 'admin_url': '/admin/oauth2_provider/refreshtoken/', 'add_url': '/admin/oauth2_provider/refreshtoken/add/', 'object_name': 'RefreshToken', 'name': <django.utils.functional.lazy.<locals>.__proxy__ object at 0x03ADA7B0>}], 'app_url': '/admin/oauth2_provider/', 'name': 'Django OAuth Toolkit'}], 'site_title': <django.utils.functional.lazy.<locals>.__proxy__ object at 0x02F9EB90>}]"
[2016-11-17 16:37:19] DEBUG [django.db.backends:90] (0.000) SELECT "django_admin_log"."id", "django_admin_log"."action_time", "django_admin_log"."user_id", "django_admin_log"."content_type_id", "django_admin_log"."object_id", "django_admin_log"."object_repr", "django_admin_log"."action_flag", "django_admin_log"."change_message", "auths_user"."password", "auths_user"."last_login", "auths_user"."is_superuser", "auths_user"."username", "auths_user"."first_name", "auths_user"."last_name", "auths_user"."email", "auths_user"."is_staff", "auths_user"."is_active", "auths_user"."date_joined", "auths_user"."id", "auths_user"."last_hierarchy_id", "auths_user"."last_module_id", "auths_user"."person_id", "auths_user"."updated_at", "auths_user"."registered_by", "django_content_type"."id", "django_content_type"."app_label", "django_content_type"."model" FROM "django_admin_log" INNER JOIN "auths_user" ON ("django_admin_log"."user_id" = "auths_user"."id") LEFT OUTER JOIN "django_content_type" ON ("django_admin_log"."content_type_id" = "django_content_type"."id") WHERE "django_admin_log"."user_id" = '3651942c1384420da02bbf9e5eca3faa' ORDER BY "django_admin_log"."action_time" DESC LIMIT 10; args=('3651942c1384420da02bbf9e5eca3faa',)
[2016-11-17 16:37:19] INFO [django.server:131] "GET /admin/ HTTP/1.1" 200 10333
[2016-11-17 16:37:19] INFO [django.server:131] "GET /static/admin/css/base.css HTTP/1.1" 200 15937
[2016-11-17 16:37:19] INFO [django.server:131] "GET /static/admin/css/dashboard.css HTTP/1.1" 200 434
[2016-11-17 16:37:19] INFO [django.server:131] "GET /static/admin/css/fonts.css HTTP/1.1" 200 423
[2016-11-17 16:37:19] INFO [django.server:131] "GET /static/admin/img/icon-changelink.svg HTTP/1.1" 200 380
[2016-11-17 16:37:19] INFO [django.server:131] "GET /static/admin/img/icon-addlink.svg HTTP/1.1" 200 331
[2016-11-17 16:37:19] INFO [django.server:131] "GET /static/admin/fonts/Roboto-Regular-webfont.woff HTTP/1.1" 200 80304
[2016-11-17 16:37:19] INFO [django.server:131] "GET /static/admin/fonts/Roboto-Light-webfont.woff HTTP/1.1" 200 81348
[2016-11-17 16:37:19] INFO [django.server:131] "GET /static/admin/fonts/Roboto-Bold-webfont.woff HTTP/1.1" 200 82564
[2016-11-17 17:42:33] WARNING [django.server:131] "GET /api/auths/usermenu/ HTTP/1.1" 401 58
[2016-11-17 17:42:33] WARNING [django.server:131] "GET /api/auths/localuserinfo/ HTTP/1.1" 401 58
[2016-11-17 17:42:35] DEBUG [django.db.backends:90] (0.000) SELECT "auths_menu"."router_json" FROM "auths_menu" ORDER BY "auths_menu"."pos" ASC; args=()
[2016-11-17 17:42:35] INFO [django.server:131] "GET /api/auths/routers/ HTTP/1.1" 200 2
[2016-11-17 17:42:59] DEBUG [django.db.backends:90] (0.000) SELECT "oauth2_provider_application"."id", "oauth2_provider_application"."client_id", "oauth2_provider_application"."user_id", "oauth2_provider_application"."redirect_uris", "oauth2_provider_application"."client_type", "oauth2_provider_application"."authorization_grant_type", "oauth2_provider_application"."client_secret", "oauth2_provider_application"."name", "oauth2_provider_application"."skip_authorization" FROM "oauth2_provider_application" WHERE "oauth2_provider_application"."client_id" = 'gyEJ310NDKMKrYvOMbwSnu9UFkJkXE5E48dCLRZK'; args=('gyEJ310NDKMKrYvOMbwSnu9UFkJkXE5E48dCLRZK',)
[2016-11-17 17:42:59] DEBUG [django.db.backends:90] (0.000) SELECT "auths_user"."password", "auths_user"."last_login", "auths_user"."is_superuser", "auths_user"."username", "auths_user"."first_name", "auths_user"."last_name", "auths_user"."email", "auths_user"."is_staff", "auths_user"."is_active", "auths_user"."date_joined", "auths_user"."id", "auths_user"."last_hierarchy_id", "auths_user"."last_module_id", "auths_user"."person_id", "auths_user"."updated_at", "auths_user"."registered_by" FROM "auths_user" WHERE "auths_user"."username" = 'admin'; args=('admin',)
[2016-11-17 17:42:59] DEBUG [django.db.backends:90] (0.000) BEGIN; args=None
[2016-11-17 17:42:59] DEBUG [django.db.backends:90] (0.001) INSERT INTO "oauth2_provider_accesstoken" ("user_id", "token", "application_id", "expires", "scope") VALUES ('3651942c1384420da02bbf9e5eca3faa', 'xoZTbQstwuhfuKA9SXDcRMVEFYLgIQ', 1, '2016-11-18 08:42:59.202844', 'write read'); args=['3651942c1384420da02bbf9e5eca3faa', 'xoZTbQstwuhfuKA9SXDcRMVEFYLgIQ', 1, '2016-11-18 08:42:59.202844', 'write read']
[2016-11-17 17:42:59] DEBUG [django.db.backends:90] (0.000) BEGIN; args=None
[2016-11-17 17:42:59] DEBUG [django.db.backends:90] (0.001) INSERT INTO "oauth2_provider_refreshtoken" ("user_id", "token", "application_id", "access_token_id") VALUES ('3651942c1384420da02bbf9e5eca3faa', 'gbJ8kN0ypQNE3Z8VjXb8G8KLAi0gGb', 1, 4); args=['3651942c1384420da02bbf9e5eca3faa', 'gbJ8kN0ypQNE3Z8VjXb8G8KLAi0gGb', 1, 4]
[2016-11-17 17:42:59] INFO [django.server:131] "POST /o/token/ HTTP/1.1" 200 169
[2016-11-17 17:43:00] INFO [django.server:131] "OPTIONS /api/auths/localuserinfo/ HTTP/1.1" 200 0
[2016-11-17 17:43:00] INFO [django.server:131] "OPTIONS /api/auths/usermenu/ HTTP/1.1" 200 0
[2016-11-17 17:43:00] DEBUG [django.db.backends:90] (0.002) SELECT "oauth2_provider_accesstoken"."id", "oauth2_provider_accesstoken"."user_id", "oauth2_provider_accesstoken"."token", "oauth2_provider_accesstoken"."application_id", "oauth2_provider_accesstoken"."expires", "oauth2_provider_accesstoken"."scope", "auths_user"."password", "auths_user"."last_login", "auths_user"."is_superuser", "auths_user"."username", "auths_user"."first_name", "auths_user"."last_name", "auths_user"."email", "auths_user"."is_staff", "auths_user"."is_active", "auths_user"."date_joined", "auths_user"."id", "auths_user"."last_hierarchy_id", "auths_user"."last_module_id", "auths_user"."person_id", "auths_user"."updated_at", "auths_user"."registered_by", "oauth2_provider_application"."id", "oauth2_provider_application"."client_id", "oauth2_provider_application"."user_id", "oauth2_provider_application"."redirect_uris", "oauth2_provider_application"."client_type", "oauth2_provider_application"."authorization_grant_type", "oauth2_provider_application"."client_secret", "oauth2_provider_application"."name", "oauth2_provider_application"."skip_authorization" FROM "oauth2_provider_accesstoken" LEFT OUTER JOIN "auths_user" ON ("oauth2_provider_accesstoken"."user_id" = "auths_user"."id") INNER JOIN "oauth2_provider_application" ON ("oauth2_provider_accesstoken"."application_id" = "oauth2_provider_application"."id") WHERE "oauth2_provider_accesstoken"."token" = 'xoZTbQstwuhfuKA9SXDcRMVEFYLgIQ'; args=('xoZTbQstwuhfuKA9SXDcRMVEFYLgIQ',)
[2016-11-17 17:43:00] DEBUG [django.db.backends:90] (0.001) SELECT "oauth2_provider_accesstoken"."id", "oauth2_provider_accesstoken"."user_id", "oauth2_provider_accesstoken"."token", "oauth2_provider_accesstoken"."application_id", "oauth2_provider_accesstoken"."expires", "oauth2_provider_accesstoken"."scope", "auths_user"."password", "auths_user"."last_login", "auths_user"."is_superuser", "auths_user"."username", "auths_user"."first_name", "auths_user"."last_name", "auths_user"."email", "auths_user"."is_staff", "auths_user"."is_active", "auths_user"."date_joined", "auths_user"."id", "auths_user"."last_hierarchy_id", "auths_user"."last_module_id", "auths_user"."person_id", "auths_user"."updated_at", "auths_user"."registered_by", "oauth2_provider_application"."id", "oauth2_provider_application"."client_id", "oauth2_provider_application"."user_id", "oauth2_provider_application"."redirect_uris", "oauth2_provider_application"."client_type", "oauth2_provider_application"."authorization_grant_type", "oauth2_provider_application"."client_secret", "oauth2_provider_application"."name", "oauth2_provider_application"."skip_authorization" FROM "oauth2_provider_accesstoken" LEFT OUTER JOIN "auths_user" ON ("oauth2_provider_accesstoken"."user_id" = "auths_user"."id") INNER JOIN "oauth2_provider_application" ON ("oauth2_provider_accesstoken"."application_id" = "oauth2_provider_application"."id") WHERE "oauth2_provider_accesstoken"."token" = 'xoZTbQstwuhfuKA9SXDcRMVEFYLgIQ'; args=('xoZTbQstwuhfuKA9SXDcRMVEFYLgIQ',)
[2016-11-17 17:43:00] DEBUG [django.db.backends:90] (0.000) SELECT "auths_menu"."id" FROM "auths_menu" WHERE ("auths_menu"."id" IS NOT NULL AND "auths_menu"."is_active" = 1 AND "auths_menu"."module" = 'BACKEND') ORDER BY "auths_menu"."pos" ASC; args=(True, 'BACKEND')
[2016-11-17 17:43:00] DEBUG [django.db.backends:90] (0.000) SELECT "auth_group"."id", "auth_group"."name" FROM "auth_group" INNER JOIN "auths_user_groups" ON ("auth_group"."id" = "auths_user_groups"."group_id") WHERE "auths_user_groups"."user_id" = '3651942c1384420da02bbf9e5eca3faa'; args=('3651942c1384420da02bbf9e5eca3faa',)
[2016-11-17 17:43:00] DEBUG [django.db.backends:90] (0.003) SELECT (1) AS "a" FROM "django_session" WHERE "django_session"."session_key" = '0c6wsjuhke45944xf2d4cwmvdq552hzw' LIMIT 1; args=('0c6wsjuhke45944xf2d4cwmvdq552hzw',)
[2016-11-17 17:43:00] DEBUG [django.db.backends:90] (0.000) BEGIN; args=None
[2016-11-17 17:43:00] DEBUG [django.db.backends:90] (0.001) SELECT "auth_permission"."id", "auth_permission"."name", "auth_permission"."content_type_id", "auth_permission"."codename" FROM "auth_permission" INNER JOIN "auths_user_user_permissions" ON ("auth_permission"."id" = "auths_user_user_permissions"."permission_id") INNER JOIN "django_content_type" ON ("auth_permission"."content_type_id" = "django_content_type"."id") WHERE "auths_user_user_permissions"."user_id" = '3651942c1384420da02bbf9e5eca3faa' ORDER BY "django_content_type"."app_label" ASC, "django_content_type"."model" ASC, "auth_permission"."codename" ASC; args=('3651942c1384420da02bbf9e5eca3faa',)
[2016-11-17 17:43:00] INFO [django.server:131] "GET /api/auths/localuserinfo/ HTTP/1.1" 200 496
[2016-11-17 17:43:00] DEBUG [django.db.backends:90] (0.000) INSERT INTO "django_session" ("session_key", "session_data", "expire_date") SELECT '0c6wsjuhke45944xf2d4cwmvdq552hzw', 'NmE3M2Q3NmYwOTU3YjJmZDBjYmQxYTVjODc5MTExNzM3NjY1YzYzNzp7Il9zZXNzaW9uX2V4cGlyeSI6MzB9', '2016-11-17 22:43:30.444153'; args=('0c6wsjuhke45944xf2d4cwmvdq552hzw', 'NmE3M2Q3NmYwOTU3YjJmZDBjYmQxYTVjODc5MTExNzM3NjY1YzYzNzp7Il9zZXNzaW9uX2V4cGlyeSI6MzB9', '2016-11-17 22:43:30.444153')
[2016-11-17 17:43:00] INFO [django.server:131] "GET /api/auths/usermenu/ HTTP/1.1" 200 11
[2016-11-17 17:43:22] INFO [django.server:131] "OPTIONS /api/catalogo/autors/ HTTP/1.1" 200 0
[2016-11-17 17:43:22] DEBUG [django.db.backends:90] (0.001) SELECT "oauth2_provider_accesstoken"."id", "oauth2_provider_accesstoken"."user_id", "oauth2_provider_accesstoken"."token", "oauth2_provider_accesstoken"."application_id", "oauth2_provider_accesstoken"."expires", "oauth2_provider_accesstoken"."scope", "auths_user"."password", "auths_user"."last_login", "auths_user"."is_superuser", "auths_user"."username", "auths_user"."first_name", "auths_user"."last_name", "auths_user"."email", "auths_user"."is_staff", "auths_user"."is_active", "auths_user"."date_joined", "auths_user"."id", "auths_user"."last_hierarchy_id", "auths_user"."last_module_id", "auths_user"."person_id", "auths_user"."updated_at", "auths_user"."registered_by", "oauth2_provider_application"."id", "oauth2_provider_application"."client_id", "oauth2_provider_application"."user_id", "oauth2_provider_application"."redirect_uris", "oauth2_provider_application"."client_type", "oauth2_provider_application"."authorization_grant_type", "oauth2_provider_application"."client_secret", "oauth2_provider_application"."name", "oauth2_provider_application"."skip_authorization" FROM "oauth2_provider_accesstoken" LEFT OUTER JOIN "auths_user" ON ("oauth2_provider_accesstoken"."user_id" = "auths_user"."id") INNER JOIN "oauth2_provider_application" ON ("oauth2_provider_accesstoken"."application_id" = "oauth2_provider_application"."id") WHERE "oauth2_provider_accesstoken"."token" = 'xoZTbQstwuhfuKA9SXDcRMVEFYLgIQ'; args=('xoZTbQstwuhfuKA9SXDcRMVEFYLgIQ',)
[2016-11-17 17:43:22] DEBUG [django.db.backends:90] (0.000) SELECT COUNT(*) AS "__count" FROM "catalogo_autor"; args=()
[2016-11-17 17:43:22] INFO [django.server:131] "GET /api/catalogo/autors/ HTTP/1.1" 200 124
[2016-11-17 17:43:34] DEBUG [django.db.backends:90] (0.001) SELECT "oauth2_provider_accesstoken"."id", "oauth2_provider_accesstoken"."user_id", "oauth2_provider_accesstoken"."token", "oauth2_provider_accesstoken"."application_id", "oauth2_provider_accesstoken"."expires", "oauth2_provider_accesstoken"."scope", "auths_user"."password", "auths_user"."last_login", "auths_user"."is_superuser", "auths_user"."username", "auths_user"."first_name", "auths_user"."last_name", "auths_user"."email", "auths_user"."is_staff", "auths_user"."is_active", "auths_user"."date_joined", "auths_user"."id", "auths_user"."last_hierarchy_id", "auths_user"."last_module_id", "auths_user"."person_id", "auths_user"."updated_at", "auths_user"."registered_by", "oauth2_provider_application"."id", "oauth2_provider_application"."client_id", "oauth2_provider_application"."user_id", "oauth2_provider_application"."redirect_uris", "oauth2_provider_application"."client_type", "oauth2_provider_application"."authorization_grant_type", "oauth2_provider_application"."client_secret", "oauth2_provider_application"."name", "oauth2_provider_application"."skip_authorization" FROM "oauth2_provider_accesstoken" LEFT OUTER JOIN "auths_user" ON ("oauth2_provider_accesstoken"."user_id" = "auths_user"."id") INNER JOIN "oauth2_provider_application" ON ("oauth2_provider_accesstoken"."application_id" = "oauth2_provider_application"."id") WHERE "oauth2_provider_accesstoken"."token" = 'xoZTbQstwuhfuKA9SXDcRMVEFYLgIQ'; args=('xoZTbQstwuhfuKA9SXDcRMVEFYLgIQ',)
[2016-11-17 17:43:34] DEBUG [django.db.backends:90] (0.000) SELECT COUNT(*) AS "__count" FROM "catalogo_autor"; args=()
[2016-11-17 17:43:34] INFO [django.server:131] "GET /api/catalogo/autors/ HTTP/1.1" 200 124
[2016-11-17 17:45:36] DEBUG [django.db.backends:90] (0.000) 
            SELECT name, type FROM sqlite_master
            WHERE type in ('table', 'view') AND NOT name='sqlite_sequence'
            ORDER BY name; args=None
[2016-11-17 17:45:36] DEBUG [django.db.backends:90] (0.000) SELECT "django_migrations"."app", "django_migrations"."name" FROM "django_migrations"; args=()
[2016-11-17 17:45:46] DEBUG [django.db.backends:90] (0.001) 
            SELECT name, type FROM sqlite_master
            WHERE type in ('table', 'view') AND NOT name='sqlite_sequence'
            ORDER BY name; args=None
[2016-11-17 17:45:46] DEBUG [django.db.backends:90] (0.000) SELECT "django_migrations"."app", "django_migrations"."name" FROM "django_migrations"; args=()
[2016-11-17 17:45:46] DEBUG [django.db.backends:90] (0.000) 
            SELECT name, type FROM sqlite_master
            WHERE type in ('table', 'view') AND NOT name='sqlite_sequence'
            ORDER BY name; args=None
[2016-11-17 17:45:46] DEBUG [django.db.backends:90] (0.000) SELECT "django_migrations"."app", "django_migrations"."name" FROM "django_migrations"; args=()
[2016-11-17 17:45:46] DEBUG [django.db.backends:90] (0.000) PRAGMA foreign_keys; args=None
[2016-11-17 17:45:46] DEBUG [django.db.backends:90] (0.000) PRAGMA foreign_keys = 0; args=None
[2016-11-17 17:45:46] DEBUG [django.db.backends:90] (0.000) BEGIN; args=None
[2016-11-17 17:45:46] DEBUG [django.db.backends.schema:103] CREATE TABLE "catalogo_cliente" ("id" char(32) NOT NULL PRIMARY KEY, "nombre" varchar(60) NOT NULL, "codigo" varchar(15) NULL, "estado" bool NOT NULL); (params None)
[2016-11-17 17:45:46] DEBUG [django.db.backends:90] (0.001) CREATE TABLE "catalogo_cliente" ("id" char(32) NOT NULL PRIMARY KEY, "nombre" varchar(60) NOT NULL, "codigo" varchar(15) NULL, "estado" bool NOT NULL); args=None
[2016-11-17 17:45:47] DEBUG [django.db.backends:90] (0.000) PRAGMA foreign_keys = 0; args=None
[2016-11-17 17:45:47] DEBUG [django.db.backends:90] (0.001) 
            SELECT name, type FROM sqlite_master
            WHERE type in ('table', 'view') AND NOT name='sqlite_sequence'
            ORDER BY name; args=None
[2016-11-17 17:45:47] DEBUG [django.db.backends:90] (0.000) BEGIN; args=None
[2016-11-17 17:45:47] DEBUG [django.db.backends:90] (0.001) INSERT INTO "django_migrations" ("app", "name", "applied") VALUES ('catalogo', '0002_cliente', '2016-11-17 22:45:47.035421'); args=['catalogo', '0002_cliente', '2016-11-17 22:45:47.035421']
[2016-11-17 17:45:47] DEBUG [django.db.backends:90] (0.000) 
            SELECT name, type FROM sqlite_master
            WHERE type in ('table', 'view') AND NOT name='sqlite_sequence'
            ORDER BY name; args=None
[2016-11-17 17:45:47] DEBUG [django.db.backends:90] (0.000) SELECT "django_migrations"."app", "django_migrations"."name" FROM "django_migrations"; args=()
[2016-11-17 17:45:47] DEBUG [django.db.backends:90] (0.000) SELECT "django_content_type"."id", "django_content_type"."app_label", "django_content_type"."model" FROM "django_content_type" WHERE ("django_content_type"."app_label" = 'admin' AND "django_content_type"."model" = 'logentry'); args=('admin', 'logentry')
[2016-11-17 17:45:47] DEBUG [django.db.backends:90] (0.000) SELECT "auth_permission"."content_type_id", "auth_permission"."codename" FROM "auth_permission" INNER JOIN "django_content_type" ON ("auth_permission"."content_type_id" = "django_content_type"."id") WHERE "auth_permission"."content_type_id" IN (1) ORDER BY "django_content_type"."app_label" ASC, "django_content_type"."model" ASC, "auth_permission"."codename" ASC; args=(1,)
[2016-11-17 17:45:47] DEBUG [django.db.backends:90] (0.000) SELECT "django_content_type"."id", "django_content_type"."app_label", "django_content_type"."model" FROM "django_content_type" WHERE "django_content_type"."app_label" = 'admin'; args=('admin',)
[2016-11-17 17:45:47] DEBUG [django.db.backends:90] (0.001) SELECT "django_content_type"."id", "django_content_type"."app_label", "django_content_type"."model" FROM "django_content_type" WHERE ("django_content_type"."app_label" = 'auth' AND "django_content_type"."model" = 'permission'); args=('auth', 'permission')
[2016-11-17 17:45:47] DEBUG [django.db.backends:90] (0.000) SELECT "django_content_type"."id", "django_content_type"."app_label", "django_content_type"."model" FROM "django_content_type" WHERE ("django_content_type"."app_label" = 'auth' AND "django_content_type"."model" = 'group'); args=('auth', 'group')
[2016-11-17 17:45:47] DEBUG [django.db.backends:90] (0.000) SELECT "auth_permission"."content_type_id", "auth_permission"."codename" FROM "auth_permission" INNER JOIN "django_content_type" ON ("auth_permission"."content_type_id" = "django_content_type"."id") WHERE "auth_permission"."content_type_id" IN (2, 3) ORDER BY "django_content_type"."app_label" ASC, "django_content_type"."model" ASC, "auth_permission"."codename" ASC; args=(2, 3)
[2016-11-17 17:45:47] DEBUG [django.db.backends:90] (0.000) SELECT "django_content_type"."id", "django_content_type"."app_label", "django_content_type"."model" FROM "django_content_type" WHERE "django_content_type"."app_label" = 'auth'; args=('auth',)
[2016-11-17 17:45:47] DEBUG [django.db.backends:90] (0.000) SELECT "django_content_type"."id", "django_content_type"."app_label", "django_content_type"."model" FROM "django_content_type" WHERE ("django_content_type"."app_label" = 'contenttypes' AND "django_content_type"."model" = 'contenttype'); args=('contenttypes', 'contenttype')
[2016-11-17 17:45:47] DEBUG [django.db.backends:90] (0.000) SELECT "auth_permission"."content_type_id", "auth_permission"."codename" FROM "auth_permission" INNER JOIN "django_content_type" ON ("auth_permission"."content_type_id" = "django_content_type"."id") WHERE "auth_permission"."content_type_id" IN (4) ORDER BY "django_content_type"."app_label" ASC, "django_content_type"."model" ASC, "auth_permission"."codename" ASC; args=(4,)
[2016-11-17 17:45:47] DEBUG [django.db.backends:90] (0.000) SELECT "django_content_type"."id", "django_content_type"."app_label", "django_content_type"."model" FROM "django_content_type" WHERE "django_content_type"."app_label" = 'contenttypes'; args=('contenttypes',)
[2016-11-17 17:45:47] DEBUG [django.db.backends:90] (0.000) SELECT "django_content_type"."id", "django_content_type"."app_label", "django_content_type"."model" FROM "django_content_type" WHERE ("django_content_type"."app_label" = 'sessions' AND "django_content_type"."model" = 'session'); args=('sessions', 'session')
[2016-11-17 17:45:47] DEBUG [django.db.backends:90] (0.000) SELECT "auth_permission"."content_type_id", "auth_permission"."codename" FROM "auth_permission" INNER JOIN "django_content_type" ON ("auth_permission"."content_type_id" = "django_content_type"."id") WHERE "auth_permission"."content_type_id" IN (5) ORDER BY "django_content_type"."app_label" ASC, "django_content_type"."model" ASC, "auth_permission"."codename" ASC; args=(5,)
[2016-11-17 17:45:47] DEBUG [django.db.backends:90] (0.000) SELECT "django_content_type"."id", "django_content_type"."app_label", "django_content_type"."model" FROM "django_content_type" WHERE "django_content_type"."app_label" = 'sessions'; args=('sessions',)
[2016-11-17 17:45:47] DEBUG [django.db.backends:90] (0.000) SELECT "django_content_type"."id", "django_content_type"."app_label", "django_content_type"."model" FROM "django_content_type" WHERE ("django_content_type"."app_label" = 'corsheaders' AND "django_content_type"."model" = 'corsmodel'); args=('corsheaders', 'corsmodel')
[2016-11-17 17:45:47] DEBUG [django.db.backends:90] (0.000) SELECT "auth_permission"."content_type_id", "auth_permission"."codename" FROM "auth_permission" INNER JOIN "django_content_type" ON ("auth_permission"."content_type_id" = "django_content_type"."id") WHERE "auth_permission"."content_type_id" IN (6) ORDER BY "django_content_type"."app_label" ASC, "django_content_type"."model" ASC, "auth_permission"."codename" ASC; args=(6,)
[2016-11-17 17:45:47] DEBUG [django.db.backends:90] (0.000) SELECT "django_content_type"."id", "django_content_type"."app_label", "django_content_type"."model" FROM "django_content_type" WHERE "django_content_type"."app_label" = 'corsheaders'; args=('corsheaders',)
[2016-11-17 17:45:47] DEBUG [django.db.backends:90] (0.000) SELECT "django_content_type"."id", "django_content_type"."app_label", "django_content_type"."model" FROM "django_content_type" WHERE ("django_content_type"."app_label" = 'oauth2_provider' AND "django_content_type"."model" = 'grant'); args=('oauth2_provider', 'grant')
[2016-11-17 17:45:47] DEBUG [django.db.backends:90] (0.000) SELECT "django_content_type"."id", "django_content_type"."app_label", "django_content_type"."model" FROM "django_content_type" WHERE ("django_content_type"."app_label" = 'oauth2_provider' AND "django_content_type"."model" = 'application'); args=('oauth2_provider', 'application')
[2016-11-17 17:45:47] DEBUG [django.db.backends:90] (0.000) SELECT "django_content_type"."id", "django_content_type"."app_label", "django_content_type"."model" FROM "django_content_type" WHERE ("django_content_type"."app_label" = 'oauth2_provider' AND "django_content_type"."model" = 'accesstoken'); args=('oauth2_provider', 'accesstoken')
[2016-11-17 17:45:47] DEBUG [django.db.backends:90] (0.000) SELECT "django_content_type"."id", "django_content_type"."app_label", "django_content_type"."model" FROM "django_content_type" WHERE ("django_content_type"."app_label" = 'oauth2_provider' AND "django_content_type"."model" = 'refreshtoken'); args=('oauth2_provider', 'refreshtoken')
[2016-11-17 17:45:47] DEBUG [django.db.backends:90] (0.000) SELECT "auth_permission"."content_type_id", "auth_permission"."codename" FROM "auth_permission" INNER JOIN "django_content_type" ON ("auth_permission"."content_type_id" = "django_content_type"."id") WHERE "auth_permission"."content_type_id" IN (8, 9, 10, 7) ORDER BY "django_content_type"."app_label" ASC, "django_content_type"."model" ASC, "auth_permission"."codename" ASC; args=(8, 9, 10, 7)
[2016-11-17 17:45:47] DEBUG [django.db.backends:90] (0.000) SELECT "django_content_type"."id", "django_content_type"."app_label", "django_content_type"."model" FROM "django_content_type" WHERE "django_content_type"."app_label" = 'oauth2_provider'; args=('oauth2_provider',)
[2016-11-17 17:45:47] DEBUG [django.db.backends:90] (0.000) SELECT "django_content_type"."id", "django_content_type"."app_label", "django_content_type"."model" FROM "django_content_type" WHERE ("django_content_type"."app_label" = 'auths' AND "django_content_type"."model" = 'person'); args=('auths', 'person')
[2016-11-17 17:45:47] DEBUG [django.db.backends:90] (0.000) SELECT "django_content_type"."id", "django_content_type"."app_label", "django_content_type"."model" FROM "django_content_type" WHERE ("django_content_type"."app_label" = 'auths' AND "django_content_type"."model" = 'menu'); args=('auths', 'menu')
[2016-11-17 17:45:47] DEBUG [django.db.backends:90] (0.000) SELECT "django_content_type"."id", "django_content_type"."app_label", "django_content_type"."model" FROM "django_content_type" WHERE ("django_content_type"."app_label" = 'auths' AND "django_content_type"."model" = 'hierarchytype'); args=('auths', 'hierarchytype')
[2016-11-17 17:45:47] DEBUG [django.db.backends:90] (0.000) SELECT "django_content_type"."id", "django_content_type"."app_label", "django_content_type"."model" FROM "django_content_type" WHERE ("django_content_type"."app_label" = 'auths' AND "django_content_type"."model" = 'user'); args=('auths', 'user')
[2016-11-17 17:45:47] DEBUG [django.db.backends:90] (0.000) SELECT "django_content_type"."id", "django_content_type"."app_label", "django_content_type"."model" FROM "django_content_type" WHERE ("django_content_type"."app_label" = 'auths' AND "django_content_type"."model" = 'hierarchy'); args=('auths', 'hierarchy')
[2016-11-17 17:45:47] DEBUG [django.db.backends:90] (0.000) SELECT "django_content_type"."id", "django_content_type"."app_label", "django_content_type"."model" FROM "django_content_type" WHERE ("django_content_type"."app_label" = 'auths' AND "django_content_type"."model" = 'userhierarchypermission'); args=('auths', 'userhierarchypermission')
[2016-11-17 17:45:47] DEBUG [django.db.backends:90] (0.000) SELECT "django_content_type"."id", "django_content_type"."app_label", "django_content_type"."model" FROM "django_content_type" WHERE ("django_content_type"."app_label" = 'auths' AND "django_content_type"."model" = 'userhierarchygroup'); args=('auths', 'userhierarchygroup')
[2016-11-17 17:45:47] DEBUG [django.db.backends:90] (0.000) SELECT "auth_permission"."content_type_id", "auth_permission"."codename" FROM "auth_permission" INNER JOIN "django_content_type" ON ("auth_permission"."content_type_id" = "django_content_type"."id") WHERE "auth_permission"."content_type_id" IN (11, 12, 13, 14, 15, 16, 17) ORDER BY "django_content_type"."app_label" ASC, "django_content_type"."model" ASC, "auth_permission"."codename" ASC; args=(11, 12, 13, 14, 15, 16, 17)
[2016-11-17 17:45:47] DEBUG [django.db.backends:90] (0.000) SELECT "django_content_type"."id", "django_content_type"."app_label", "django_content_type"."model" FROM "django_content_type" WHERE "django_content_type"."app_label" = 'auths'; args=('auths',)
[2016-11-17 17:45:47] DEBUG [django.db.backends:90] (0.000) SELECT "django_content_type"."id", "django_content_type"."app_label", "django_content_type"."model" FROM "django_content_type" WHERE ("django_content_type"."app_label" = 'catalogo' AND "django_content_type"."model" = 'autor'); args=('catalogo', 'autor')
[2016-11-17 17:45:47] DEBUG [django.db.backends:90] (0.000) SELECT "django_content_type"."id", "django_content_type"."app_label", "django_content_type"."model" FROM "django_content_type" WHERE ("django_content_type"."app_label" = 'catalogo' AND "django_content_type"."model" = 'libro'); args=('catalogo', 'libro')
[2016-11-17 17:45:47] DEBUG [django.db.backends:90] (0.000) SELECT "django_content_type"."id", "django_content_type"."app_label", "django_content_type"."model" FROM "django_content_type" WHERE ("django_content_type"."app_label" = 'catalogo' AND "django_content_type"."model" = 'categoria'); args=('catalogo', 'categoria')
[2016-11-17 17:45:47] DEBUG [django.db.backends:90] (0.000) SELECT "django_content_type"."id", "django_content_type"."app_label", "django_content_type"."model" FROM "django_content_type" WHERE ("django_content_type"."app_label" = 'catalogo' AND "django_content_type"."model" = 'ejemplar'); args=('catalogo', 'ejemplar')
[2016-11-17 17:45:47] DEBUG [django.db.backends:90] (0.000) SELECT "django_content_type"."id", "django_content_type"."app_label", "django_content_type"."model" FROM "django_content_type" WHERE ("django_content_type"."app_label" = 'catalogo' AND "django_content_type"."model" = 'cliente'); args=('catalogo', 'cliente')
[2016-11-17 17:45:47] DEBUG [django.db.backends:90] (0.000) SELECT "django_content_type"."id", "django_content_type"."app_label", "django_content_type"."model" FROM "django_content_type" WHERE ("django_content_type"."app_label" = 'catalogo' AND "django_content_type"."model" = 'cliente'); args=('catalogo', 'cliente')
[2016-11-17 17:45:47] DEBUG [django.db.backends:90] (0.000) BEGIN; args=None
[2016-11-17 17:45:47] DEBUG [django.db.backends:90] (0.001) INSERT INTO "django_content_type" ("app_label", "model") VALUES ('catalogo', 'cliente'); args=['catalogo', 'cliente']
[2016-11-17 17:45:47] DEBUG [django.db.backends:90] (0.001) SELECT "auth_permission"."content_type_id", "auth_permission"."codename" FROM "auth_permission" INNER JOIN "django_content_type" ON ("auth_permission"."content_type_id" = "django_content_type"."id") WHERE "auth_permission"."content_type_id" IN (18, 19, 20, 21, 22) ORDER BY "django_content_type"."app_label" ASC, "django_content_type"."model" ASC, "auth_permission"."codename" ASC; args=(18, 19, 20, 21, 22)
[2016-11-17 17:45:47] DEBUG [django.db.backends:90] (0.000) BEGIN; args=None
[2016-11-17 17:45:47] DEBUG [django.db.backends:90] (0.001) INSERT INTO "auth_permission" ("name", "content_type_id", "codename") SELECT 'Can add cliente', 22, 'add_cliente' UNION ALL SELECT 'Can change cliente', 22, 'change_cliente' UNION ALL SELECT 'Can delete cliente', 22, 'delete_cliente' UNION ALL SELECT 'Can list cliente', 22, 'list_cliente' UNION ALL SELECT 'Can get cliente', 22, 'get_cliente'; args=('Can add cliente', 22, 'add_cliente', 'Can change cliente', 22, 'change_cliente', 'Can delete cliente', 22, 'delete_cliente', 'Can list cliente', 22, 'list_cliente', 'Can get cliente', 22, 'get_cliente')
[2016-11-17 17:45:47] DEBUG [django.db.backends:90] (0.000) SELECT "django_content_type"."id", "django_content_type"."app_label", "django_content_type"."model" FROM "django_content_type" WHERE "django_content_type"."app_label" = 'catalogo'; args=('catalogo',)
